Workbook

Sheet Planilha1
A3: Rótulos de Linha | B3: Contagem de DOCUMENTO
A4: 01 | B4: 1283
A5: 452-454 | B5: 52
A6: 454-460 | B6: 175
A7: 510-511 | B7: 72
A8: 512-NORTE | B8: 33
A9: 515-NORTE | B9: 33
A10: 515-SUL | B10: 33
A11: 520-NORTE | B11: 34
A12: 521-NORTE | B12: 24
A13: 535-545 | B13: 272
A14: 626-628 | B14: 86
A15: 634-RET | B15: 82
... A23: Total Geral | B23: 1900

Sheet LD_PROJETOS
A1: LISTA DE DOCUMENTOS
A2: PROJETO: A373 - MOTIVA PANTANAL - BR163MS | C2: ANOS: 01 e 02 | F2: DATA ATUALIZAÇÃO: 16/06/2026
A3: DOCUMENTO | B3: REVISÃO | C3: ANO | D3: GRUPO | E3: OBRA | F3: TÍTULO | G3: DISCIPLINA | H3: SIGLA | I3: PASTA | J3: ARQUIVO | K3: REV. RECEBIDAS | L3: EXTENSÕES | M3: DATA RECEBIMENTO | N3: RAIZ SHAREPOINT | O3: LINK | P3: LOCAL
A4: MSV-163MS-452-454-ACA-EXE-DE-C1-001 | B4: =VLOOKUP(LD_01[[#This Row],[DOCUMENTO]],_xlfn.SORTBY(ARQUIVOS_RECEBIDOS!$E$2:$F$5010,ARQUIVOS_RECEBIDOS!$F$2:$F$5010,-1),2,) -> R00 | C4: 01 | D4: PRINCIPAL | E4: 452-454 | F4: LEVANTAMENTO TOPOGRÁFICO - PLANTA | G4: TOPOGRAFIA | H4: =_xlfn.XLOOKUP(LD_01[[#This Row],[DISCIPLINA]],'CLASSES DE PROJETOS'!$F$3:$F$37,'CLASSES DE PROJETOS'!$C$3:$C$37) -> TO | I4: =_xlfn.TEXTJOIN("/",TRUE,"MSV-163MS-"&LD_01[[#This Row],[OBRA]],_xlfn.XLOOKUP(LD_01[[#This Row],[SIGLA]],'CLASSES DE PROJETOS'!$C$3:$C$37,'CLASSES DE PROJETOS'!$E$3:$E$37)) -> MSV-163MS-452-454/33.TO | J4: {=_xlfn.TEXTJOIN(",",TRUE,_xlfn._xlws.FILTER(ARQUIVOS[ARQUIVO],(ARQUIVOS[DOCUMENTO]=LD_01[[#This Row],[DOCUMENTO]])*(ARQUIVOS[REVISÃO]=LD_01[[#This Row],[REVISÃO]])*(ARQUIVOS[EXTENSÃO]="pdf")))} -> MSV-163MS-452-454-ACA-EXE-DE-C1-001-R00.pdf | K4: {=_xlfn.TEXTJOIN(", ",TRUE,_xlfn.UNIQUE(_xlfn._xlws.FILTER(ARQUIVOS_RECEBIDOS!$F$2:$F$5010,ARQUIVOS_RECEBIDOS!$E$2:$E$5010=LD_01[[#This Row],[DOCUMENTO]])))} -> R00 | L4: {=_xlfn.TEXTJOIN(",",TRUE,_xlfn._xlws.FILTER(ARQUIVOS[EXTENSÃO],(ARQUIVOS[DOCUMENTO]=LD_01[[#This Row],[DOCUMENTO]])*(ARQUIVOS[REVISÃO]=LD_01[[#This Row],[REVISÃO]])))} -> dwg,pdf | M4: {=_xlfn.UNIQUE(_xlfn._xlws.FILTER(ARQUIVOS[DATA RECEBIMENTO],(ARQUIVOS[DOCUMENTO]=LD_01[[#This Row],[DOCUMENTO]])*(ARQUIVOS[REVISÃO]=LD_01[[#This Row],[REVISÃO]])))} -> 45838 | N4: ="https://aterpa.sharepoint.com//sites/A373_Projetos/Documentos Compartilhados/11.Sala Tecnica/01.PROJETOS/ANO "&TEXT(LD_01[[#This Row],[ANO]],"00") -> https://aterpa.sharepoint.com//sites/A373_Projetos/Documentos Compartilhados/11.Sala Tecnica/01.PROJETOS/ANO 01 | O4: =_xlfn.TEXTJOIN("/",TRUE,LD_01[[#This Row],[RAIZ SHAREPOINT]],LD_01[[#This Row],[PASTA]],LD_01[[#This Row],[ARQUIVO]]) -> https://aterpa.sharepoint.com//sites/A373_Projetos/Documentos Compartilhados/11.Sala Tecnica/01.PROJETOS/ANO 01/MSV-163MS-452-454/33.TO/MSV-163MS-452-454-ACA-EXE-DE-C1-001-R00.pdf | P4: =LD_01[[#This Row],[PASTA]]&"/"&LD_01[[#This Row],[ARQUIVO]] -> MSV-163MS-452-454/33.TO/MSV-163MS-452-454-ACA-EXE-DE-C1-001-R00.pdf
A5: MSV-163MS-452-454-ACA-EXE-DE-C1-002 | B5: =VLOOKUP(LD_01[[#This Row],[DOCUMENTO]],_xlfn.SORTBY(ARQUIVOS_RECEBIDOS!$E$2:$F$5010,ARQUIVOS_RECEBIDOS!$F$2:$F$5010,-1),2,) -> R00 | C5: 01 | D5: PRINCIPAL | E5: 452-454 | F5: LEVANTAMENTO TOPOGRÁFICO - PLANTA | G5: TOPOGRAFIA | H5: =_xlfn.XLOOKUP(LD_01[[#This Row],[DISCIPLINA]],'CLASSES DE PROJETOS'!$F$3:$F$37,'CLASSES DE PROJETOS'!$C$3:$C$37) -> TO | I5: =_xlfn.TEXTJOIN("/",TRUE,"MSV-163MS-"&LD_01[[#This Row],[OBRA]],_xlfn.XLOOKUP(LD_01[[#This Row],[SIGLA]],'CLASSES DE PROJETOS'!$C$3:$C$37,'CLASSES DE PROJETOS'!$E$3:$E$37)) -> MSV-163MS-452-454/33.TO | J5: {=_xlfn.TEXTJOIN(",",TRUE,_xlfn._xlws.FILTER(ARQUIVOS[ARQUIVO],(ARQUIVOS[DOCUMENTO]=LD_01[[#This Row],[DOCUMENTO]])*(ARQUIVOS[REVISÃO]=LD_01[[#This Row],[REVISÃO]])*(ARQUIVOS[EXTENSÃO]="pdf")))} -> MSV-163MS-452-454-ACA-EXE-DE-C1-002-R00.pdf | K5: {=_xlfn.TEXTJOIN(", ",TRUE,_xlfn.UNIQUE(_xlfn._xlws.FILTER(ARQUIVOS_RECEBIDOS!$F$2:$F$5010,ARQUIVOS_RECEBIDOS!$E$2:$E$5010=LD_01[[#This Row],[DOCUMENTO]])))} -> R00 | L5: {=_xlfn.TEXTJOIN(",",TRUE,_xlfn._xlws.FILTER(ARQUIVOS[EXTENSÃO],(ARQUIVOS[DOCUMENTO]=LD_01[[#This Row],[DOCUMENTO]])*(ARQUIVOS[REVISÃO]=LD_01[[#This Row],[REVISÃO]])))} -> dwg,pdf | M5: {=_xlfn.UNIQUE(_xlfn._xlws.FILTER(ARQUIVOS[DATA RECEBIMENTO],(ARQUIVOS[DOCUMENTO]=LD_01[[#This Row],[DOCUMENTO]])*(ARQUIVOS[REVISÃO]=LD_01[[#This Row],[REVISÃO]])))} -> 45838 | N5: ="https://aterpa.sharepoint.com//sites/A373_Projetos/Documentos Compartilhados/11.Sala Tecnica/01.PROJETOS/ANO "&TEXT(LD_01[[#This Row],[ANO]],"00") -> https://aterpa.sharepoint.com//sites/A373_Projetos/Documentos Compartilhados/11.Sala Tecnica/01.PROJETOS/ANO 01 | O5: =_xlfn.TEXTJOIN("/",TRUE,LD_01[[#This Row],[RAIZ SHAREPOINT]],LD_01[[#This Row],[PASTA]],LD_01[[#This Row],[ARQUIVO]]) -> https://aterpa.sharepoint.com//sites/A373_Projetos/Documentos Compartilhados/11.Sala Tecnica/01.PROJETOS/ANO 01/MSV-163MS-452-454/33.TO/MSV-163MS-452-454-ACA-EXE-DE-C1-002-R00.pdf | P5: =LD_01[[#This Row],[PASTA]]&"/"&LD_01[[#This Row],[ARQUIVO]] -> MSV-163MS-452-454/33.TO/MSV-163MS-452-454-ACA-EXE-DE-C1-002-R00.pdf
A6: MSV-163MS-452-454-ACA-EXE-DE-D3-001 | B6: =VLOOKUP(LD_01[[#This Row],[DOCUMENTO]],_xlfn.SORTBY(ARQUIVOS_RECEBIDOS!$E$2:$F$5010,ARQUIVOS_RECEBIDOS!$F$2:$F$5010,-1),2,) -> R03 | C6: 01 | D6: PRINCIPAL | E6: 452-454 | F6: PLANTA E PERFIL LONGITUDINAL | G6: GEOTECNIA E GEOLOGIA | H6: =_xlfn.XLOOKUP(LD_01[[#This Row],[DISCIPLINA]],'CLASSES DE PROJETOS'!$F$3:$F$37,'CLASSES DE PROJETOS'!$C$3:$C$37) -> GG | I6: =_xlfn.TEXTJOIN("/",TRUE,"MSV-163MS-"&LD_01[[#This Row],[OBRA]],_xlfn.XLOOKUP(LD_01[[#This Row],[SIGLA]],'CLASSES DE PROJETOS'!$C$3:$C$37,'CLASSES DE PROJETOS'!$E$3:$E$37)) -> MSV-163MS-452-454/19.GG | J6: {=_xlfn.TEXTJOIN(",",TRUE,_xlfn._xlws.FILTER(ARQUIVOS[ARQUIVO],(ARQUIVOS[DOCUMENTO]=LD_01[[#This Row],[DOCUMENTO]])*(ARQUIVOS[REVISÃO]=LD_01[[#This Row],[REVISÃO]])*(ARQUIVOS[EXTENSÃO]="pdf")))} -> MSV-163MS-452-454-ACA-EXE-DE-D3-001-R03.pdf | K6: {=_xlfn.TEXTJOIN(", ",TRUE,_xlfn.UNIQUE(_xlfn._xlws.FILTER(ARQUIVOS_RECEBIDOS!$F$2:$F$5010,ARQUIVOS_RECEBIDOS!$E$2:$E$5010=LD_01[[#This Row],[DOCUMENTO]])))} -> R03 | L6: {=_xlfn.TEXTJOIN(",",TRUE,_xlfn._xlws.FILTER(ARQUIVOS[EXTENSÃO],(ARQUIVOS[DOCUMENTO]=LD_01[[#This Row],[DOCUMENTO]])*(ARQUIVOS[REVISÃO]=LD_01[[#This Row],[REVISÃO]])))} -> dwg,pdf | M6: {=_xlfn.UNIQUE(_xlfn._xlws.FILTER(ARQUIVOS[DATA RECEBIMENTO],(ARQUIVOS[DOCUMENTO]=LD_01[[#This Row],[DOCUMENTO]])*(ARQUIVOS[REVISÃO]=LD_01[[#This Row],[REVISÃO]])))} -> 45838 | N6: ="https://aterpa.sharepoint.com//sites/A373_Projetos/Documentos Compartilhados/11.Sala Tecnica/01.PROJETOS/ANO "&TEXT(LD_01[[#This Row],[ANO]],"00") -> https://aterpa.sharepoint.com//sites/A373_Projetos/Documentos Compartilhados/11.Sala Tecnica/01.PROJETOS/ANO 01 | O6: =_xlfn.TEXTJOIN("/",TRUE,LD_01[[#This Row],[RAIZ SHAREPOINT]],LD_01[[#This Row],[PASTA]],LD_01[[#This Row],[ARQUIVO]]) -> https://aterpa.sharepoint.com//sites/A373_Projetos/Documentos Compartilhados/11.Sala Tecnica/01.PROJETOS/ANO 01/MSV-163MS-452-454/19.GG/MSV-163MS-452-454-ACA-EXE-DE-D3-001-R03.pdf | P6: =LD_01[[#This Row],[PASTA]]&"/"&LD_01[[#This Row],[ARQUIVO]] -> MSV-163MS-452-454/19.GG/MSV-163MS-452-454-ACA-EXE-DE-D3-001-R03.pdf
A7: MSV-163MS-452-454-ACA-EXE-DE-D3-002 | B7: =VLOOKUP(LD_01[[#This Row],[DOCUMENTO]],_xlfn.SORTBY(ARQUIVOS_RECEBIDOS!$E$2:$F$5010,ARQUIVOS_RECEBIDOS!$F$2:$F$5010,-1),2,) -> R03 | C7: 01 | D7: PRINCIPAL | E7: 452-454 | F7: PLANTA E PERFIL LONGITUDINAL | G7: GEOTECNIA E GEOLOGIA | H7: =_xlfn.XLOOKUP(LD_01[[#This Row],[DISCIPLINA]],'CLASSES DE PROJETOS'!$F$3:$F$37,'CLASSES DE PROJETOS'!$C$3:$C$37) -> GG | I7: =_xlfn.TEXTJOIN("/",TRUE,"MSV-163MS-"&LD_01[[#This Row],[OBRA]],_xlfn.XLOOKUP(LD_01[[#This Row],[SIGLA]],'CLASSES DE PROJETOS'!$C$3:$C$37,'CLASSES DE PROJETOS'!$E$3:$E$37)) -> MSV-163MS-452-454/19.GG | J7: {=_xlfn.TEXTJOIN(",",TRUE,_xlfn._xlws.FILTER(ARQUIVOS[ARQUIVO],(ARQUIVOS[DOCUMENTO]=LD_01[[#This Row],[DOCUMENTO]])*(ARQUIVOS[REVISÃO]=LD_01[[#This Row],[REVISÃO]])*(ARQUIVOS[EXTENSÃO]="pdf")))} -> MSV-163MS-452-454-ACA-EXE-DE-D3-002-R03.pdf | K7: {=_xlfn.TEXTJOIN(", ",TRUE,_xlfn.UNIQUE(_xlfn._xlws.FILTER(ARQUIVOS_RECEBIDOS!$F$2:$F$5010,ARQUIVOS_RECEBIDOS!$E$2:$E$5010=LD_01[[#This Row],[DOCUMENTO]])))} -> R03 | L7: {=_xlfn.TEXTJOIN(",",TRUE,_xlfn._xlws.FILTER(ARQUIVOS[EXTENSÃO],(ARQUIVOS[DOCUMENTO]=LD_01[[#This Row],[DOCUMENTO]])*(ARQUIVOS[REVISÃO]=LD_01[[#This Row],[REVISÃO]])))} -> dwg,pdf | M7: {=_xlfn.UNIQUE(_xlfn._xlws.FILTER(ARQUIVOS[DATA RECEBIMENTO],(ARQUIVOS[DOCUMENTO]=LD_01[[#This Row],[DOCUMENTO]])*(ARQUIVOS[REVISÃO]=LD_01[[#This Row],[REVISÃO]])))} -> 45838 | N7: ="https://aterpa.sharepoint.com//sites/A373_Projetos/Documentos Compartilhados/11.Sala Tecnica/01.PROJETOS/ANO "&TEXT(LD_01[[#This Row],[ANO]],"00") -> https://aterpa.sharepoint.com//sites/A373_Projetos/Documentos Compartilhados/11.Sala Tecnica/01.PROJETOS/ANO 01 | O7: =_xlfn.TEXTJOIN("/",TRUE,LD_01[[#This Row],[RAIZ SHAREPOINT]],LD_01[[#This Row],[PASTA]],LD_01[[#This Row],[ARQUIVO]]) -> https://aterpa.sharepoint.com//sites/A373_Projetos/Documentos Compartilhados/11.Sala Tecnica/01.PROJETOS/ANO 01/MSV-163MS-452-454/19.GG/MSV-163MS-452-454-ACA-EXE-DE-D3-002-R03.pdf | P7: =LD_01[[#This Row],[PASTA]]&"/"&LD_01[[#This Row],[ARQUIVO]] -> MSV-163MS-452-454/19.GG/MSV-163MS-452-454-ACA-EXE-DE-D3-002-R03.pdf
A8: MSV-163MS-452-454-ACA-EXE-DE-D3-003 | B8: =VLOOKUP(LD_01[[#This Row],[DOCUMENTO]],_xlfn.SORTBY(ARQUIVOS_RECEBIDOS!$E$2:$F$5010,ARQUIVOS_RECEBIDOS!$F$2:$F$5010,-1),2,) -> R02 | C8: 01 | D8: PRINCIPAL | E8: 452-454 | F8: PLANTA E PERFIL LONGITUDINAL | G8: GEOTECNIA E GEOLOGIA | H8: =_xlfn.XLOOKUP(LD_01[[#This Row],[DISCIPLINA]],'CLASSES DE PROJETOS'!$F$3:$F$37,'CLASSES DE PROJETOS'!$C$3:$C$37) -> GG | I8: =_xlfn.TEXTJOIN("/",TRUE,"MSV-163MS-"&LD_01[[#This Row],[OBRA]],_xlfn.XLOOKUP(LD_01[[#This Row],[SIGLA]],'CLASSES DE PROJETOS'!$C$3:$C$37,'CLASSES DE PROJETOS'!$E$3:$E$37)) -> MSV-163MS-452-454/19.GG | J8: {=_xlfn.TEXTJOIN(",",TRUE,_xlfn._xlws.FILTER(ARQUIVOS[ARQUIVO],(ARQUIVOS[DOCUMENTO]=LD_01[[#This Row],[DOCUMENTO]])*(ARQUIVOS[REVISÃO]=LD_01[[#This Row],[REVISÃO]])*(ARQUIVOS[EXTENSÃO]="pdf")))} -> MSV-163MS-452-454-ACA-EXE-DE-D3-003-R02.pdf | K8: {=_xlfn.TEXTJOIN(", ",TRUE,_xlfn.UNIQUE(_xlfn._xlws.FILTER(ARQUIVOS_RECEBIDOS!$F$2:$F$5010,ARQUIVOS_RECEBIDOS!$E$2:$E$5010=LD_01[[#This Row],[DOCUMENTO]])))} -> R02 | L8: {=_xlfn.TEXTJOIN(",",TRUE,_xlfn._xlws.FILTER(ARQUIVOS[EXTENSÃO],(ARQUIVOS[DOCUMENTO]=LD_01[[#This Row],[DOCUMENTO]])*(ARQUIVOS[REVISÃO]=LD_01[[#This Row],[REVISÃO]])))} -> dwg,pdf | M8: {=_xlfn.UNIQUE(_xlfn._xlws.FILTER(ARQUIVOS[DATA RECEBIMENTO],(ARQUIVOS[DOCUMENTO]=LD_01[[#This Row],[DOCUMENTO]])*(ARQUIVOS[REVISÃO]=LD_01[[#This Row],[REVISÃO]])))} -> 45838 | N8: ="https://aterpa.sharepoint.com//sites/A373_Projetos/Documentos Compartilhados/11.Sala Tecnica/01.PROJETOS/ANO "&TEXT(LD_01[[#This Row],[ANO]],"00") -> https://aterpa.sharepoint.com//sites/A373_Projetos/Documentos Compartilhados/11.Sala Tecnica/01.PROJETOS/ANO 01 | O8: =_xlfn.TEXTJOIN("/",TRUE,LD_01[[#This Row],[RAIZ SHAREPOINT]],LD_01[[#This Row],[PASTA]],LD_01[[#This Row],[ARQUIVO]]) -> https://aterpa.sharepoint.com//sites/A373_Projetos/Documentos Compartilhados/11.Sala Tecnica/01.PROJETOS/ANO 01/MSV-163MS-452-454/19.GG/MSV-163MS-452-454-ACA-EXE-DE-D3-003-R02.pdf | P8: =LD_01[[#This Row],[PASTA]]&"/"&LD_01[[#This Row],[ARQUIVO]] -> MSV-163MS-452-454/19.GG/MSV-163MS-452-454-ACA-EXE-DE-D3-003-R02.pdf
A9: MSV-163MS-452-454-ACA-EXE-DE-F1-001 | B9: =VLOOKUP(LD_01[[#This Row],[DOCUMENTO]],_xlfn.SORTBY(ARQUIVOS_RECEBIDOS!$E$2:$F$5010,ARQUIVOS_RECEBIDOS!$F$2:$F$5010,-1),2,) -> R07 | C9: 01 | D9: PRINCIPAL | E9: 452-454 | F9: PROJETO EXECUTIVO DE GEOMETRIA - PLANTA E PERFIL LONGITUDINAL | G9: GEOMÉTRICO | H9: =_xlfn.XLOOKUP(LD_01[[#This Row],[DISCIPLINA]],'CLASSES DE PROJETOS'!$F$3:$F$37,'CLASSES DE PROJETOS'!$C$3:$C$37) -> GE | I9: =_xlfn.TEXTJOIN("/",TRUE,"MSV-163MS-"&LD_01[[#This Row],[OBRA]],_xlfn.XLOOKUP(LD_01[[#This Row],[SIGLA]],'CLASSES DE PROJETOS'!$C$3:$C$37,'CLASSES DE PROJETOS'!$E$3:$E$37)) -> MSV-163MS-452-454/18.GE | J9: {=_xlfn.TEXTJOIN(",",TRUE,_xlfn._xlws.FILTER(ARQUIVOS[ARQUIVO],(ARQUIVOS[DOCUMENTO]=LD_01[[#This Row],[DOCUMENTO]])*(ARQUIVOS[REVISÃO]=LD_01[[#This Row],[REVISÃO]])*(ARQUIVOS[EXTENSÃO]="pdf")))} -> MSV-163MS-452-454-ACA-EXE-DE-F1-001-R07.pdf | K9: {=_xlfn.TEXTJOIN(", ",TRUE,_xlfn.UNIQUE(_xlfn._xlws.FILTER(ARQUIVOS_RECEBIDOS!$F$2:$F$5010,ARQUIVOS_RECEBIDOS!$E$2:$E$5010=LD_01[[#This Row],[DOCUMENTO]])))} -> R07 | L9: {=_xlfn.TEXTJOIN(",",TRUE,_xlfn._xlws.FILTER(ARQUIVOS[EXTENSÃO],(ARQUIVOS[DOCUMENTO]=LD_01[[#This Row],[DOCUMENTO]])*(ARQUIVOS[REVISÃO]=LD_01[[#This Row],[REVISÃO]])))} -> dwg,pdf | M9: {=_xlfn.UNIQUE(_xlfn._xlws.FILTER(ARQUIVOS[DATA RECEBIMENTO],(ARQUIVOS[DOCUMENTO]=LD_01[[#This Row],[DOCUMENTO]])*(ARQUIVOS[REVISÃO]=LD_01[[#This Row],[REVISÃO]])))} -> 45838 | N9: ="https://aterpa.sharepoint.com//sites/A373_Projetos/Documentos Compartilhados/11.Sala Tecnica/01.PROJETOS/ANO "&TEXT(LD_01[[#This Row],[ANO]],"00") -> https://aterpa.sharepoint.com//sites/A373_Projetos/Documentos Compartilhados/11.Sala Tecnica/01.PROJETOS/ANO 01 | O9: =_xlfn.TEXTJOIN("/",TRUE,LD_01[[#This Row],[RAIZ SHAREPOINT]],LD_01[[#This Row],[PASTA]],LD_01[[#This Row],[ARQUIVO]]) -> https://aterpa.sharepoint.com//sites/A373_Projetos/Documentos Compartilhados/11.Sala Tecnica/01.PROJETOS/ANO 01/MSV-163MS-452-454/18.GE/MSV-163MS-452-454-ACA-EXE-DE-F1-001-R07.pdf | P9: =LD_01[[#This Row],[PASTA]]&"/"&LD_01[[#This Row],[ARQUIVO]] -> MSV-163MS-452-454/18.GE/MSV-163MS-452-454-ACA-EXE-DE-F1-001-R07.pdf
A10: MSV-163MS-452-454-ACA-EXE-DE-F1-002 | B10: =VLOOKUP(LD_01[[#This Row],[DOCUMENTO]],_xlfn.SORTBY(ARQUIVOS_RECEBIDOS!$E$2:$F$5010,ARQUIVOS_RECEBIDOS!$F$2:$F$5010,-1),2,) -> R05 | C10: 01 | D10: PRINCIPAL | E10: 452-454 | F10: PROJETO EXECUTIVO DE GEOMETRIA - PLANTA E PERFIL LONGITUDINAL | G10: GEOMÉTRICO | H10: =_xlfn.XLOOKUP(LD_01[[#This Row],[DISCIPLINA]],'CLASSES DE PROJETOS'!$F$3:$F$37,'CLASSES DE PROJETOS'!$C$3:$C$37) -> GE | I10: =_xlfn.TEXTJOIN("/",TRUE,"MSV-163MS-"&LD_01[[#This Row],[OBRA]],_xlfn.XLOOKUP(LD_01[[#This Row],[SIGLA]],'CLASSES DE PROJETOS'!$C$3:$C$37,'CLASSES DE PROJETOS'!$E$3:$E$37)) -> MSV-163MS-452-454/18.GE | J10: {=_xlfn.TEXTJOIN(",",TRUE,_xlfn._xlws.FILTER(ARQUIVOS[ARQUIVO],(ARQUIVOS[DOCUMENTO]=LD_01[[#This Row],[DOCUMENTO]])*(ARQUIVOS[REVISÃO]=LD_01[[#This Row],[REVISÃO]])*(ARQUIVOS[EXTENSÃO]="pdf")))} -> MSV-163MS-452-454-ACA-EXE-DE-F1-002-R05.pdf | K10: {=_xlfn.TEXTJOIN(", ",TRUE,_xlfn.UNIQUE(_xlfn._xlws.FILTER(ARQUIVOS_RECEBIDOS!$F$2:$F$5010,ARQUIVOS_RECEBIDOS!$E$2:$E$5010=LD_01[[#This Row],[DOCUMENTO]])))} -> R05 | L10: {=_xlfn.TEXTJOIN(",",TRUE,_xlfn._xlws.FILTER(ARQUIVOS[EXTENSÃO],(ARQUIVOS[DOCUMENTO]=LD_01[[#This Row],[DOCUMENTO]])*(ARQUIVOS[REVISÃO]=LD_01[[#This Row],[REVISÃO]])))} -> dwg,pdf | M10: {=_xlfn.UNIQUE(_xlfn._xlws.FILTER(ARQUIVOS[DATA RECEBIMENTO],(ARQUIVOS[DOCUMENTO]=LD_01[[#This Row],[DOCUMENTO]])*(ARQUIVOS[REVISÃO]=LD_01[[#This Row],[REVISÃO]])))} -> 45838 | N10: ="https://aterpa.sharepoint.com//sites/A373_Projetos/Documentos Compartilhados/11.Sala Tecnica/01.PROJETOS/ANO "&TEXT(LD_01[[#This Row],[ANO]],"00") -> https://aterpa.sharepoint.com//sites/A373_Projetos/Documentos Compartilhados/11.Sala Tecnica/01.PROJETOS/ANO 01 | O10: =_xlfn.TEXTJOIN("/",TRUE,LD_01[[#This Row],[RAIZ SHAREPOINT]],LD_01[[#This Row],[PASTA]],LD_01[[#This Row],[ARQUIVO]]) -> https://aterpa.sharepoint.com//sites/A373_Projetos/Documentos Compartilhados/11.Sala Tecnica/01.PROJETOS/ANO 01/MSV-163MS-452-454/18.GE/MSV-163MS-452-454-ACA-EXE-DE-F1-002-R05.pdf | P10: =LD_01[[#This Row],[PASTA]]&"/"&LD_01[[#This Row],[ARQUIVO]] -> MSV-163MS-452-454/18.GE/MSV-163MS-452-454-ACA-EXE-DE-F1-002-R05.pdf
A11: MSV-163MS-452-454-ACA-EXE-DE-F1-003 | B11: =VLOOKUP(LD_01[[#This Row],[DOCUMENTO]],_xlfn.SORTBY(ARQUIVOS_RECEBIDOS!$E$2:$F$5010,ARQUIVOS_RECEBIDOS!$F$2:$F$5010,-1),2,) -> R04 | C11: 01 | D11: PRINCIPAL | E11: 452-454 | F11: PROJETO EXECUTIVO DE GEOMETRIA - PLANTA E PERFIL LONGITUDINAL | G11: GEOMÉTRICO | H11: =_xlfn.XLOOKUP(LD_01[[#This Row],[DISCIPLINA]],'CLASSES DE PROJETOS'!$F$3:$F$37,'CLASSES DE PROJETOS'!$C$3:$C$37) -> GE | I11: =_xlfn.TEXTJOIN("/",TRUE,"MSV-163MS-"&LD_01[[#This Row],[OBRA]],_xlfn.XLOOKUP(LD_01[[#This Row],[SIGLA]],'CLASSES DE PROJETOS'!$C$3:$C$37,'CLASSES DE PROJETOS'!$E$3:$E$37)) -> MSV-163MS-452-454/18.GE | J11: {=_xlfn.TEXTJOIN(",",TRUE,_xlfn._xlws.FILTER(ARQUIVOS[ARQUIVO],(ARQUIVOS[DOCUMENTO]=LD_01[[#This Row],[DOCUMENTO]])*(ARQUIVOS[REVISÃO]=LD_01[[#This Row],[REVISÃO]])*(ARQUIVOS[EXTENSÃO]="pdf")))} -> MSV-163MS-452-454-ACA-EXE-DE-F1-003-R04.pdf | K11: {=_xlfn.TEXTJOIN(", ",TRUE,_xlfn.UNIQUE(_xlfn._xlws.FILTER(ARQUIVOS_RECEBIDOS!$F$2:$F$5010,ARQUIVOS_RECEBIDOS!$E$2:$E$5010=LD_01[[#This Row],[DOCUMENTO]])))} -> R04 | L11: {=_xlfn.TEXTJOIN(",",TRUE,_xlfn._xlws.FILTER(ARQUIVOS[EXTENSÃO],(ARQUIVOS[DOCUMENTO]=LD_01[[#This Row],[DOCUMENTO]])*(ARQUIVOS[REVISÃO]=LD_01[[#This Row],[REVISÃO]])))} -> dwg,pdf | M11: {=_xlfn.UNIQUE(_xlfn._xlws.FILTER(ARQUIVOS[DATA RECEBIMENTO],(ARQUIVOS[DOCUMENTO]=LD_01[[#This Row],[DOCUMENTO]])*(ARQUIVOS[REVISÃO]=LD_01[[#This Row],[REVISÃO]])))} -> 45838 | N11: ="https://aterpa.sharepoint.com//sites/A373_Projetos/Documentos Compartilhados/11.Sala Tecnica/01.PROJETOS/ANO "&TEXT(LD_01[[#This Row],[ANO]],"00") -> https://aterpa.sharepoint.com//sites/A373_Projetos/Documentos Compartilhados/11.Sala Tecnica/01.PROJETOS/ANO 01 | O11: =_xlfn.TEXTJOIN("/",TRUE,LD_01[[#This Row],[RAIZ SHAREPOINT]],LD_01[[#This Row],[PASTA]],LD_01[[#This Row],[ARQUIVO]]) -> https://aterpa.sharepoint.com//sites/A373_Projetos/Documentos Compartilhados/11.Sala Tecnica/01.PROJETOS/ANO 01/MSV-163MS-452-454/18.GE/MSV-163MS-452-454-ACA-EXE-DE-F1-003-R04.pdf | P11: =LD_01[[#This Row],[PASTA]]&"/"&LD_01[[#This Row],[ARQUIVO]] -> MSV-163MS-452-454/18.GE/MSV-163MS-452-454-ACA-EXE-DE-F1-003-R04.pdf
A12: MSV-163MS-452-454-ACA-EXE-DE-F1-004 | B12: =VLOOKUP(LD_01[[#This Row],[DOCUMENTO]],_xlfn.SORTBY(ARQUIVOS_RECEBIDOS!$E$2:$F$5010,ARQUIVOS_RECEBIDOS!$F$2:$F$5010,-1),2,) -> R03 | C12: 01 | D12: PRINCIPAL | E12: 452-454 | F12: PROJETO EXECUTIVO DE GEOMETRIA - SEÇÕES TIPO | G12: GEOMÉTRICO | H12: =_xlfn.XLOOKUP(LD_01[[#This Row],[DISCIPLINA]],'CLASSES DE PROJETOS'!$F$3:$F$37,'CLASSES DE PROJETOS'!$C$3:$C$37) -> GE | I12: =_xlfn.TEXTJOIN("/",TRUE,"MSV-163MS-"&LD_01[[#This Row],[OBRA]],_xlfn.XLOOKUP(LD_01[[#This Row],[SIGLA]],'CLASSES DE PROJETOS'!$C$3:$C$37,'CLASSES DE PROJETOS'!$E$3:$E$37)) -> MSV-163MS-452-454/18.GE | J12: {=_xlfn.TEXTJOIN(",",TRUE,_xlfn._xlws.FILTER(ARQUIVOS[ARQUIVO],(ARQUIVOS[DOCUMENTO]=LD_01[[#This Row],[DOCUMENTO]])*(ARQUIVOS[REVISÃO]=LD_01[[#This Row],[REVISÃO]])*(ARQUIVOS[EXTENSÃO]="pdf")))} -> MSV-163MS-452-454-ACA-EXE-DE-F1-004-R03.pdf | K12: {=_xlfn.TEXTJOIN(", ",TRUE,_xlfn.UNIQUE(_xlfn._xlws.FILTER(ARQUIVOS_RECEBIDOS!$F$2:$F$5010,ARQUIVOS_RECEBIDOS!$E$2:$E$5010=LD_01[[#This Row],[DOCUMENTO]])))} -> R03 | L12: {=_xlfn.TEXTJOIN(",",TRUE,_xlfn._xlws.FILTER(ARQUIVOS[EXTENSÃO],(ARQUIVOS[DOCUMENTO]=LD_01[[#This Row],[DOCUMENTO]])*(ARQUIVOS[REVISÃO]=LD_01[[#This Row],[REVISÃO]])))} -> dwg,pdf | M12: {=_xlfn.UNIQUE(_xlfn._xlws.FILTER(ARQUIVOS[DATA RECEBIMENTO],(ARQUIVOS[DOCUMENTO]=LD_01[[#This Row],[DOCUMENTO]])*(ARQUIVOS[REVISÃO]=LD_01[[#This Row],[REVISÃO]])))} -> 45838 | N12: ="https://aterpa.sharepoint.com//sites/A373_Projetos/Documentos Compartilhados/11.Sala Tecnica/01.PROJETOS/ANO "&TEXT(LD_01[[#This Row],[ANO]],"00") -> https://aterpa.sharepoint.com//sites/A373_Projetos/Documentos Compartilhados/11.Sala Tecnica/01.PROJETOS/ANO 01 | O12: =_xlfn.TEXTJOIN("/",TRUE,LD_01[[#This Row],[RAIZ SHAREPOINT]],LD_01[[#This Row],[PASTA]],LD_01[[#This Row],[ARQUIVO]]) -> https://aterpa.sharepoint.com//sites/A373_Projetos/Documentos Compartilhados/11.Sala Tecnica/01.PROJETOS/ANO 01/MSV-163MS-452-454/18.GE/MSV-163MS-452-454-ACA-EXE-DE-F1-004-R03.pdf | P12: =LD_01[[#This Row],[PASTA]]&"/"&LD_01[[#This Row],[ARQUIVO]] -> MSV-163MS-452-454/18.GE/MSV-163MS-452-454-ACA-EXE-DE-F1-004-R03.pdf
A13: MSV-163MS-452-454-ACA-EXE-DE-G1-001 | B13: =VLOOKUP(LD_01[[#This Row],[DOCUMENTO]],_xlfn.SORTBY(ARQUIVOS_RECEBIDOS!$E$2:$F$5010,ARQUIVOS_RECEBIDOS!$F$2:$F$5010,-1),2,) -> R04 | C13: 01 | D13: PRINCIPAL | E13: 452-454 | F13: PROJETO DE TERRAPLENAGEM - PLANTA DE DISTRIBUIÇÃO | G13: TERRAPLENAGEM | H13: =_xlfn.XLOOKUP(LD_01[[#This Row],[DISCIPLINA]],'CLASSES DE PROJETOS'!$F$3:$F$37,'CLASSES DE PROJETOS'!$C$3:$C$37) -> TE | I13: =_xlfn.TEXTJOIN("/",TRUE,"MSV-163MS-"&LD_01[[#This Row],[OBRA]],_xlfn.XLOOKUP(LD_01[[#This Row],[SIGLA]],'CLASSES DE PROJETOS'!$C$3:$C$37,'CLASSES DE PROJETOS'!$E$3:$E$37)) -> MSV-163MS-452-454/32.TE | J13: {=_xlfn.TEXTJOIN(",",TRUE,_xlfn._xlws.FILTER(ARQUIVOS[ARQUIVO],(ARQUIVOS[DOCUMENTO]=LD_01[[#This Row],[DOCUMENTO]])*(ARQUIVOS[REVISÃO]=LD_01[[#This Row],[REVISÃO]])*(ARQUIVOS[EXTENSÃO]="pdf")))} -> MSV-163MS-452-454-ACA-EXE-DE-G1-001-R04.pdf | K13: {=_xlfn.TEXTJOIN(", ",TRUE,_xlfn.UNIQUE(_xlfn._xlws.FILTER(ARQUIVOS_RECEBIDOS!$F$2:$F$5010,ARQUIVOS_RECEBIDOS!$E$2:$E$5010=LD_01[[#This Row],[DOCUMENTO]])))} -> R04 | L13: {=_xlfn.TEXTJOIN(",",TRUE,_xlfn._xlws.FILTER(ARQUIVOS[EXTENSÃO],(ARQUIVOS[DOCUMENTO]=LD_01[[#This Row],[DOCUMENTO]])*(ARQUIVOS[REVISÃO]=LD_01[[#This Row],[REVISÃO]])))} -> dwg,pdf | M13: {=_xlfn.UNIQUE(_xlfn._xlws.FILTER(ARQUIVOS[DATA RECEBIMENTO],(ARQUIVOS[DOCUMENTO]=LD_01[[#This Row],[DOCUMENTO]])*(ARQUIVOS[REVISÃO]=LD_01[[#This Row],[REVISÃO]])))} -> 45838 | N13: ="https://aterpa.sharepoint.com//sites/A373_Projetos/Documentos Compartilhados/11.Sala Tecnica/01.PROJETOS/ANO "&TEXT(LD_01[[#This Row],[ANO]],"00") -> https://aterpa.sharepoint.com//sites/A373_Projetos/Documentos Compartilhados/11.Sala Tecnica/01.PROJETOS/ANO 01 | O13: =_xlfn.TEXTJOIN("/",TRUE,LD_01[[#This Row],[RAIZ SHAREPOINT]],LD_01[[#This Row],[PASTA]],LD_01[[#This Row],[ARQUIVO]]) -> https://aterpa.sharepoint.com//sites/A373_Projetos/Documentos Compartilhados/11.Sala Tecnica/01.PROJETOS/ANO 01/MSV-163MS-452-454/32.TE/MSV-163MS-452-454-ACA-EXE-DE-G1-001-R04.pdf | P13: =LD_01[[#This Row],[PASTA]]&"/"&LD_01[[#This Row],[ARQUIVO]] -> MSV-163MS-452-454/32.TE/MSV-163MS-452-454-ACA-EXE-DE-G1-001-R04.pdf
A14: MSV-163MS-452-454-ACA-EXE-DE-G1-002 | B14: =VLOOKUP(LD_01[[#This Row],[DOCUMENTO]],_xlfn.SORTBY(ARQUIVOS_RECEBIDOS!$E$2:$F$5010,ARQUIVOS_RECEBIDOS!$F$2:$F$5010,-1),2,) -> R04 | C14: 01 | D14: PRINCIPAL | E14: 452-454 | F14: PROJETO DE TERRAPLENAGEM - PLANTA DE DISTRIBUIÇÃO | G14: TERRAPLENAGEM | H14: =_xlfn.XLOOKUP(LD_01[[#This Row],[DISCIPLINA]],'CLASSES DE PROJETOS'!$F$3:$F$37,'CLASSES DE PROJETOS'!$C$3:$C$37) -> TE | I14: =_xlfn.TEXTJOIN("/",TRUE,"MSV-163MS-"&LD_01[[#This Row],[OBRA]],_xlfn.XLOOKUP(LD_01[[#This Row],[SIGLA]],'CLASSES DE PROJETOS'!$C$3:$C$37,'CLASSES DE PROJETOS'!$E$3:$E$37)) -> MSV-163MS-452-454/32.TE | J14: {=_xlfn.TEXTJOIN(",",TRUE,_xlfn._xlws.FILTER(ARQUIVOS[ARQUIVO],(ARQUIVOS[DOCUMENTO]=LD_01[[#This Row],[DOCUMENTO]])*(ARQUIVOS[REVISÃO]=LD_01[[#This Row],[REVISÃO]])*(ARQUIVOS[EXTENSÃO]="pdf")))} -> MSV-163MS-452-454-ACA-EXE-DE-G1-002-R04.pdf | K14: {=_xlfn.TEXTJOIN(", ",TRUE,_xlfn.UNIQUE(_xlfn._xlws.FILTER(ARQUIVOS_RECEBIDOS!$F$2:$F$5010,ARQUIVOS_RECEBIDOS!$E$2:$E$5010=LD_01[[#This Row],[DOCUMENTO]])))} -> R04 | L14: {=_xlfn.TEXTJOIN(",",TRUE,_xlfn._xlws.FILTER(ARQUIVOS[EXTENSÃO],(ARQUIVOS[DOCUMENTO]=LD_01[[#This Row],[DOCUMENTO]])*(ARQUIVOS[REVISÃO]=LD_01[[#This Row],[REVISÃO]])))} -> dwg,pdf | M14: {=_xlfn.UNIQUE(_xlfn._xlws.FILTER(ARQUIVOS[DATA RECEBIMENTO],(ARQUIVOS[DOCUMENTO]=LD_01[[#This Row],[DOCUMENTO]])*(ARQUIVOS[REVISÃO]=LD_01[[#This Row],[REVISÃO]])))} -> 45838 | N14: ="https://aterpa.sharepoint.com//sites/A373_Projetos/Documentos Compartilhados/11.Sala Tecnica/01.PROJETOS/ANO "&TEXT(LD_01[[#This Row],[ANO]],"00") -> https://aterpa.sharepoint.com//sites/A373_Projetos/Documentos Compartilhados/11.Sala Tecnica/01.PROJETOS/ANO 01 | O14: =_xlfn.TEXTJOIN("/",TRUE,LD_01[[#This Row],[RAIZ SHAREPOINT]],LD_01[[#This Row],[PASTA]],LD_01[[#This Row],[ARQUIVO]]) -> https://aterpa.sharepoint.com//sites/A373_Projetos/Documentos Compartilhados/11.Sala Tecnica/01.PROJETOS/ANO 01/MSV-163MS-452-454/32.TE/MSV-163MS-452-454-ACA-EXE-DE-G1-002-R04.pdf | P14: =LD_01[[#This Row],[PASTA]]&"/"&LD_01[[#This Row],[ARQUIVO]] -> MSV-163MS-452-454/32.TE/MSV-163MS-452-454-ACA-EXE-DE-G1-002-R04.pdf
A15: MSV-163MS-452-454-ACA-EXE-DE-G1-003 | B15: =VLOOKUP(LD_01[[#This Row],[DOCUMENTO]],_xlfn.SORTBY(ARQUIVOS_RECEBIDOS!$E$2:$F$5010,ARQUIVOS_RECEBIDOS!$F$2:$F$5010,-1),2,) -> R04 | C15: 01 | D15: PRINCIPAL | E15: 452-454 | F15: PROJETO DE TERRAPLENAGEM - PLANTA DE DISTRIBUIÇÃO | G15: TERRAPLENAGEM | H15: =_xlfn.XLOOKUP(LD_01[[#This Row],[DISCIPLINA]],'CLASSES DE PROJETOS'!$F$3:$F$37,'CLASSES DE PROJETOS'!$C$3:$C$37) -> TE | I15: =_xlfn.TEXTJOIN("/",TRUE,"MSV-163MS-"&LD_01[[#This Row],[OBRA]],_xlfn.XLOOKUP(LD_01[[#This Row],[SIGLA]],'CLASSES DE PROJETOS'!$C$3:$C$37,'CLASSES DE PROJETOS'!$E$3:$E$37)) -> MSV-163MS-452-454/32.TE | J15: {=_xlfn.TEXTJOIN(",",TRUE,_xlfn._xlws.FILTER(ARQUIVOS[ARQUIVO],(ARQUIVOS[DOCUMENTO]=LD_01[[#This Row],[DOCUMENTO]])*(ARQUIVOS[REVISÃO]=LD_01[[#This Row],[REVISÃO]])*(ARQUIVOS[EXTENSÃO]="pdf")))} -> MSV-163MS-452-454-ACA-EXE-DE-G1-003-R04.pdf | K15: {=_xlfn.TEXTJOIN(", ",TRUE,_xlfn.UNIQUE(_xlfn._xlws.FILTER(ARQUIVOS_RECEBIDOS!$F$2:$F$5010,ARQUIVOS_RECEBIDOS!$E$2:$E$5010=LD_01[[#This Row],[DOCUMENTO]])))} -> R04 | L15: {=_xlfn.TEXTJOIN(",",TRUE,_xlfn._xlws.FILTER(ARQUIVOS[EXTENSÃO],(ARQUIVOS[DOCUMENTO]=LD_01[[#This Row],[DOCUMENTO]])*(ARQUIVOS[REVISÃO]=LD_01[[#This Row],[REVISÃO]])))} -> dwg,pdf | M15: {=_xlfn.UNIQUE(_xlfn._xlws.FILTER(ARQUIVOS[DATA RECEBIMENTO],(ARQUIVOS[DOCUMENTO]=LD_01[[#This Row],[DOCUMENTO]])*(ARQUIVOS[REVISÃO]=LD_01[[#This Row],[REVISÃO]])))} -> 45838 | N15: ="https://aterpa.sharepoint.com//sites/A373_Projetos/Documentos Compartilhados/11.Sala Tecnica/01.PROJETOS/ANO "&TEXT(LD_01[[#This Row],[ANO]],"00") -> https://aterpa.sharepoint.com//sites/A373_Projetos/Documentos Compartilhados/11.Sala Tecnica/01.PROJETOS/ANO 01 | O15: =_xlfn.TEXTJOIN("/",TRUE,LD_01[[#This Row],[RAIZ SHAREPOINT]],LD_01[[#This Row],[PASTA]],LD_01[[#This Row],[ARQUIVO]]) -> https://aterpa.sharepoint.com//sites/A373_Projetos/Documentos Compartilhados/11.Sala Tecnica/01.PROJETOS/ANO 01/MSV-163MS-452-454/32.TE/MSV-163MS-452-454-ACA-EXE-DE-G1-003-R04.pdf | P15: =LD_01[[#This Row],[PASTA]]&"/"&LD_01[[#This Row],[ARQUIVO]] -> MSV-163MS-452-454/32.TE/MSV-163MS-452-454-ACA-EXE-DE-G1-003-R04.pdf
... A1720: MSV-163MS-373-385-ACA-EXE-DE-H2-115 | B1720: =VLOOKUP(LD_01[[#This Row],[DOCUMENTO]],_xlfn.SORTBY(ARQUIVOS_RECEBIDOS!$E$2:$F$5010,ARQUIVOS_RECEBIDOS!$F$2:$F$5010,-1),2,) -> R00.1 | C1720: 02 | D1720: PRINCIPAL | E1720: 373-385 | F1720: PISTA PRINCIPAL - PROJETO DE DRENAGEM E OAC - PROJETO TIPO GRELHA PARA DR-5A | G1720: DRENAGEM | H1720: =_xlfn.XLOOKUP(LD_01[[#This Row],[DISCIPLINA]],'CLASSES DE PROJETOS'!$F$3:$F$37,'CLASSES DE PROJETOS'!$C$3:$C$37) -> DR | I1720: =_xlfn.TEXTJOIN("/",TRUE,"MSV-163MS-"&LD_01[[#This Row],[OBRA]],_xlfn.XLOOKUP(LD_01[[#This Row],[SIGLA]],'CLASSES DE PROJETOS'!$C$3:$C$37,'CLASSES DE PROJETOS'!$E$3:$E$37)) -> MSV-163MS-373-385/10.DR | J1720: {=_xlfn.TEXTJOIN(",",TRUE,_xlfn._xlws.FILTER(ARQUIVOS[ARQUIVO],(ARQUIVOS[DOCUMENTO]=LD_01[[#This Row],[DOCUMENTO]])*(ARQUIVOS[REVISÃO]=LD_01[[#This Row],[REVISÃO]])*(ARQUIVOS[EXTENSÃO]="pdf")))} -> MSV-163MS-373-385-ACA-EXE-DE-H2-115-R00.1.pdf | K1720: {=_xlfn.TEXTJOIN(", ",TRUE,_xlfn.UNIQUE(_xlfn._xlws.FILTER(ARQUIVOS_RECEBIDOS!$F$2:$F$5010,ARQUIVOS_RECEBIDOS!$E$2:$E$5010=LD_01[[#This Row],[DOCUMENTO]])))} -> R00.1 | L1720: {=_xlfn.TEXTJOIN(",",TRUE,_xlfn._xlws.FILTER(ARQUIVOS[EXTENSÃO],(ARQUIVOS[DOCUMENTO]=LD_01[[#This Row],[DOCUMENTO]])*(ARQUIVOS[REVISÃO]=LD_01[[#This Row],[REVISÃO]])))} -> dwg,pdf | M1720: {=_xlfn.UNIQUE(_xlfn._xlws.FILTER(ARQUIVOS[DATA RECEBIMENTO],(ARQUIVOS[DOCUMENTO]=LD_01[[#This Row],[DOCUMENTO]])*(ARQUIVOS[REVISÃO]=LD_01[[#This Row],[REVISÃO]])))} -> 46041 | N1720: ="https://aterpa.sharepoint.com//sites/A373_Projetos/Documentos Compartilhados/11.Sala Tecnica/01.PROJETOS/ANO "&TEXT(LD_01[[#This Row],[ANO]],"00") -> https://aterpa.sharepoint.com//sites/A373_Projetos/Documentos Compartilhados/11.Sala Tecnica/01.PROJETOS/ANO 02 | O1720: =_xlfn.TEXTJOIN("/",TRUE,LD_01[[#This Row],[RAIZ SHAREPOINT]],LD_01[[#This Row],[PASTA]],LD_01[[#This Row],[ARQUIVO]]) -> https://aterpa.sharepoint.com//sites/A373_Projetos/Documentos Compartilhados/11.Sala Tecnica/01.PROJETOS/ANO 02/MSV-163MS-373-385/10.DR/MSV-163MS-373-385-ACA-EXE-DE-H2-115-R00.1.pdf | P1720: =LD_01[[#This Row],[PASTA]]&"/"&LD_01[[#This Row],[ARQUIVO]] -> MSV-163MS-373-385/10.DR/MSV-163MS-373-385-ACA-EXE-DE-H2-115-R00.1.pdf
A1721: MSV-163MS-373-385-ACA-EXE-DE-H2-116 | B1721: =VLOOKUP(LD_01[[#This Row],[DOCUMENTO]],_xlfn.SORTBY(ARQUIVOS_RECEBIDOS!$E$2:$F$5010,ARQUIVOS_RECEBIDOS!$F$2:$F$5010,-1),2,) -> R00.1 | C1721: 02 | D1721: PRINCIPAL | E1721: 373-385 | G1721: DRENAGEM | H1721: =_xlfn.XLOOKUP(LD_01[[#This Row],[DISCIPLINA]],'CLASSES DE PROJETOS'!$F$3:$F$37,'CLASSES DE PROJETOS'!$C$3:$C$37) -> DR | I1721: =_xlfn.TEXTJOIN("/",TRUE,"MSV-163MS-"&LD_01[[#This Row],[OBRA]],_xlfn.XLOOKUP(LD_01[[#This Row],[SIGLA]],'CLASSES DE PROJETOS'!$C$3:$C$37,'CLASSES DE PROJETOS'!$E$3:$E$37)) -> MSV-163MS-373-385/10.DR | J1721: {=_xlfn.TEXTJOIN(",",TRUE,_xlfn._xlws.FILTER(ARQUIVOS[ARQUIVO],(ARQUIVOS[DOCUMENTO]=LD_01[[#This Row],[DOCUMENTO]])*(ARQUIVOS[REVISÃO]=LD_01[[#This Row],[REVISÃO]])*(ARQUIVOS[EXTENSÃO]="pdf")))} -> MSV-163MS-373-385-ACA-EXE-DE-H2-116-R00.1.pdf | K1721: {=_xlfn.TEXTJOIN(", ",TRUE,_xlfn.UNIQUE(_xlfn._xlws.FILTER(ARQUIVOS_RECEBIDOS!$F$2:$F$5010,ARQUIVOS_RECEBIDOS!$E$2:$E$5010=LD_01[[#This Row],[DOCUMENTO]])))} -> R00.1 | L1721: {=_xlfn.TEXTJOIN(",",TRUE,_xlfn._xlws.FILTER(ARQUIVOS[EXTENSÃO],(ARQUIVOS[DOCUMENTO]=LD_01[[#This Row],[DOCUMENTO]])*(ARQUIVOS[REVISÃO]=LD_01[[#This Row],[REVISÃO]])))} -> dwg,pdf | M1721: {=_xlfn.UNIQUE(_xlfn._xlws.FILTER(ARQUIVOS[DATA RECEBIMENTO],(ARQUIVOS[DOCUMENTO]=LD_01[[#This Row],[DOCUMENTO]])*(ARQUIVOS[REVISÃO]=LD_01[[#This Row],[REVISÃO]])))} -> 46041 | N1721: ="https://aterpa.sharepoint.com//sites/A373_Projetos/Documentos Compartilhados/11.Sala Tecnica/01.PROJETOS/ANO "&TEXT(LD_01[[#This Row],[ANO]],"00") -> https://aterpa.sharepoint.com//sites/A373_Projetos/Documentos Compartilhados/11.Sala Tecnica/01.PROJETOS/ANO 02 | O1721: =_xlfn.TEXTJOIN("/",TRUE,LD_01[[#This Row],[RAIZ SHAREPOINT]],LD_01[[#This Row],[PASTA]],LD_01[[#This Row],[ARQUIVO]]) -> https://aterpa.sharepoint.com//sites/A373_Projetos/Documentos Compartilhados/11.Sala Tecnica/01.PROJETOS/ANO 02/MSV-163MS-373-385/10.DR/MSV-163MS-373-385-ACA-EXE-DE-H2-116-R00.1.pdf | P1721: =LD_01[[#This Row],[PASTA]]&"/"&LD_01[[#This Row],[ARQUIVO]] -> MSV-163MS-373-385/10.DR/MSV-163MS-373-385-ACA-EXE-DE-H2-116-R00.1.pdf
A1722: MSV-163MS-373-385-ACA-EXE-DE-H2-201 | B1722: =VLOOKUP(LD_01[[#This Row],[DOCUMENTO]],_xlfn.SORTBY(ARQUIVOS_RECEBIDOS!$E$2:$F$5010,ARQUIVOS_RECEBIDOS!$F$2:$F$5010,-1),2,) -> R00.2 | C1722: 02 | D1722: PRINCIPAL | E1722: 373-385 | F1722: PISTA PRINCIPAL - PROJETO DE DRENAGEM E OAC - PLANTA E PERFIL DO CANAL | G1722: DRENAGEM | H1722: =_xlfn.XLOOKUP(LD_01[[#This Row],[DISCIPLINA]],'CLASSES DE PROJETOS'!$F$3:$F$37,'CLASSES DE PROJETOS'!$C$3:$C$37) -> DR | I1722: =_xlfn.TEXTJOIN("/",TRUE,"MSV-163MS-"&LD_01[[#This Row],[OBRA]],_xlfn.XLOOKUP(LD_01[[#This Row],[SIGLA]],'CLASSES DE PROJETOS'!$C$3:$C$37,'CLASSES DE PROJETOS'!$E$3:$E$37)) -> MSV-163MS-373-385/10.DR | J1722: {=_xlfn.TEXTJOIN(",",TRUE,_xlfn._xlws.FILTER(ARQUIVOS[ARQUIVO],(ARQUIVOS[DOCUMENTO]=LD_01[[#This Row],[DOCUMENTO]])*(ARQUIVOS[REVISÃO]=LD_01[[#This Row],[REVISÃO]])*(ARQUIVOS[EXTENSÃO]="pdf")))} -> MSV-163MS-373-385-ACA-EXE-DE-H2-201-R00.2.pdf | K1722: {=_xlfn.TEXTJOIN(", ",TRUE,_xlfn.UNIQUE(_xlfn._xlws.FILTER(ARQUIVOS_RECEBIDOS!$F$2:$F$5010,ARQUIVOS_RECEBIDOS!$E$2:$E$5010=LD_01[[#This Row],[DOCUMENTO]])))} -> R00.2 | L1722: {=_xlfn.TEXTJOIN(",",TRUE,_xlfn._xlws.FILTER(ARQUIVOS[EXTENSÃO],(ARQUIVOS[DOCUMENTO]=LD_01[[#This Row],[DOCUMENTO]])*(ARQUIVOS[REVISÃO]=LD_01[[#This Row],[REVISÃO]])))} -> dwg,pdf | M1722: {=_xlfn.UNIQUE(_xlfn._xlws.FILTER(ARQUIVOS[DATA RECEBIMENTO],(ARQUIVOS[DOCUMENTO]=LD_01[[#This Row],[DOCUMENTO]])*(ARQUIVOS[REVISÃO]=LD_01[[#This Row],[REVISÃO]])))} -> 46041 | N1722: ="https://aterpa.sharepoint.com//sites/A373_Projetos/Documentos Compartilhados/11.Sala Tecnica/01.PROJETOS/ANO "&TEXT(LD_01[[#This Row],[ANO]],"00") -> https://aterpa.sharepoint.com//sites/A373_Projetos/Documentos Compartilhados/11.Sala Tecnica/01.PROJETOS/ANO 02 | O1722: =_xlfn.TEXTJOIN("/",TRUE,LD_01[[#This Row],[RAIZ SHAREPOINT]],LD_01[[#This Row],[PASTA]],LD_01[[#This Row],[ARQUIVO]]) -> https://aterpa.sharepoint.com//sites/A373_Projetos/Documentos Compartilhados/11.Sala Tecnica/01.PROJETOS/ANO 02/MSV-163MS-373-385/10.DR/MSV-163MS-373-385-ACA-EXE-DE-H2-201-R00.2.pdf | P1722: =LD_01[[#This Row],[PASTA]]&"/"&LD_01[[#This Row],[ARQUIVO]] -> MSV-163MS-373-385/10.DR/MSV-163MS-373-385-ACA-EXE-DE-H2-201-R00.2.pdf
A1723: MSV-163MS-373-385-ACA-EXE-DE-H2-202 | B1723: =VLOOKUP(LD_01[[#This Row],[DOCUMENTO]],_xlfn.SORTBY(ARQUIVOS_RECEBIDOS!$E$2:$F$5010,ARQUIVOS_RECEBIDOS!$F$2:$F$5010,-1),2,) -> R00.2 | C1723: 02 | D1723: PRINCIPAL | E1723: 373-385 | F1723: PISTA PRINCIPAL - PROJETO DE DRENAGEM E OAC - PERFIL DO CANAL | G1723: DRENAGEM | H1723: =_xlfn.XLOOKUP(LD_01[[#This Row],[DISCIPLINA]],'CLASSES DE PROJETOS'!$F$3:$F$37,'CLASSES DE PROJETOS'!$C$3:$C$37) -> DR | I1723: =_xlfn.TEXTJOIN("/",TRUE,"MSV-163MS-"&LD_01[[#This Row],[OBRA]],_xlfn.XLOOKUP(LD_01[[#This Row],[SIGLA]],'CLASSES DE PROJETOS'!$C$3:$C$37,'CLASSES DE PROJETOS'!$E$3:$E$37)) -> MSV-163MS-373-385/10.DR | J1723: {=_xlfn.TEXTJOIN(",",TRUE,_xlfn._xlws.FILTER(ARQUIVOS[ARQUIVO],(ARQUIVOS[DOCUMENTO]=LD_01[[#This Row],[DOCUMENTO]])*(ARQUIVOS[REVISÃO]=LD_01[[#This Row],[REVISÃO]])*(ARQUIVOS[EXTENSÃO]="pdf")))} -> MSV-163MS-373-385-ACA-EXE-DE-H2-202-R00.2.pdf | K1723: {=_xlfn.TEXTJOIN(", ",TRUE,_xlfn.UNIQUE(_xlfn._xlws.FILTER(ARQUIVOS_RECEBIDOS!$F$2:$F$5010,ARQUIVOS_RECEBIDOS!$E$2:$E$5010=LD_01[[#This Row],[DOCUMENTO]])))} -> R00.2 | L1723: {=_xlfn.TEXTJOIN(",",TRUE,_xlfn._xlws.FILTER(ARQUIVOS[EXTENSÃO],(ARQUIVOS[DOCUMENTO]=LD_01[[#This Row],[DOCUMENTO]])*(ARQUIVOS[REVISÃO]=LD_01[[#This Row],[REVISÃO]])))} -> dwg,pdf | M1723: {=_xlfn.UNIQUE(_xlfn._xlws.FILTER(ARQUIVOS[DATA RECEBIMENTO],(ARQUIVOS[DOCUMENTO]=LD_01[[#This Row],[DOCUMENTO]])*(ARQUIVOS[REVISÃO]=LD_01[[#This Row],[REVISÃO]])))} -> 46041 | N1723: ="https://aterpa.sharepoint.com//sites/A373_Projetos/Documentos Compartilhados/11.Sala Tecnica/01.PROJETOS/ANO "&TEXT(LD_01[[#This Row],[ANO]],"00") -> https://aterpa.sharepoint.com//sites/A373_Projetos/Documentos Compartilhados/11.Sala Tecnica/01.PROJETOS/ANO 02 | O1723: =_xlfn.TEXTJOIN("/",TRUE,LD_01[[#This Row],[RAIZ SHAREPOINT]],LD_01[[#This Row],[PASTA]],LD_01[[#This Row],[ARQUIVO]]) -> https://aterpa.sharepoint.com//sites/A373_Projetos/Documentos Compartilhados/11.Sala Tecnica/01.PROJETOS/ANO 02/MSV-163MS-373-385/10.DR/MSV-163MS-373-385-ACA-EXE-DE-H2-202-R00.2.pdf | P1723: =LD_01[[#This Row],[PASTA]]&"/"&LD_01[[#This Row],[ARQUIVO]] -> MSV-163MS-373-385/10.DR/MSV-163MS-373-385-ACA-EXE-DE-H2-202-R00.2.pdf
A1724: MSV-163MS-373-385-ACA-EXE-DE-H2-203 | B1724: =VLOOKUP(LD_01[[#This Row],[DOCUMENTO]],_xlfn.SORTBY(ARQUIVOS_RECEBIDOS!$E$2:$F$5010,ARQUIVOS_RECEBIDOS!$F$2:$F$5010,-1),2,) -> R00.2 | C1724: 02 | D1724: PRINCIPAL | E1724: 373-385 | F1724: PISTA PRINCIPAL - PROJETO DE DRENAGEM E OAC - SEÇÕES TRANSVERSAIS DO CANAL | G1724: DRENAGEM | H1724: =_xlfn.XLOOKUP(LD_01[[#This Row],[DISCIPLINA]],'CLASSES DE PROJETOS'!$F$3:$F$37,'CLASSES DE PROJETOS'!$C$3:$C$37) -> DR | I1724: =_xlfn.TEXTJOIN("/",TRUE,"MSV-163MS-"&LD_01[[#This Row],[OBRA]],_xlfn.XLOOKUP(LD_01[[#This Row],[SIGLA]],'CLASSES DE PROJETOS'!$C$3:$C$37,'CLASSES DE PROJETOS'!$E$3:$E$37)) -> MSV-163MS-373-385/10.DR | J1724: {=_xlfn.TEXTJOIN(",",TRUE,_xlfn._xlws.FILTER(ARQUIVOS[ARQUIVO],(ARQUIVOS[DOCUMENTO]=LD_01[[#This Row],[DOCUMENTO]])*(ARQUIVOS[REVISÃO]=LD_01[[#This Row],[REVISÃO]])*(ARQUIVOS[EXTENSÃO]="pdf")))} -> MSV-163MS-373-385-ACA-EXE-DE-H2-203-R00.2.pdf | K1724: {=_xlfn.TEXTJOIN(", ",TRUE,_xlfn.UNIQUE(_xlfn._xlws.FILTER(ARQUIVOS_RECEBIDOS!$F$2:$F$5010,ARQUIVOS_RECEBIDOS!$E$2:$E$5010=LD_01[[#This Row],[DOCUMENTO]])))} -> R00.2 | L1724: {=_xlfn.TEXTJOIN(",",TRUE,_xlfn._xlws.FILTER(ARQUIVOS[EXTENSÃO],(ARQUIVOS[DOCUMENTO]=LD_01[[#This Row],[DOCUMENTO]])*(ARQUIVOS[REVISÃO]=LD_01[[#This Row],[REVISÃO]])))} -> dwg,pdf | M1724: {=_xlfn.UNIQUE(_xlfn._xlws.FILTER(ARQUIVOS[DATA RECEBIMENTO],(ARQUIVOS[DOCUMENTO]=LD_01[[#This Row],[DOCUMENTO]])*(ARQUIVOS[REVISÃO]=LD_01[[#This Row],[REVISÃO]])))} -> 46041 | N1724: ="https://aterpa.sharepoint.com//sites/A373_Projetos/Documentos Compartilhados/11.Sala Tecnica/01.PROJETOS/ANO "&TEXT(LD_01[[#This Row],[ANO]],"00") -> https://aterpa.sharepoint.com//sites/A373_Projetos/Documentos Compartilhados/11.Sala Tecnica/01.PROJETOS/ANO 02 | O1724: =_xlfn.TEXTJOIN("/",TRUE,LD_01[[#This Row],[RAIZ SHAREPOINT]],LD_01[[#This Row],[PASTA]],LD_01[[#This Row],[ARQUIVO]]) -> https://aterpa.sharepoint.com//sites/A373_Projetos/Documentos Compartilhados/11.Sala Tecnica/01.PROJETOS/ANO 02/MSV-163MS-373-385/10.DR/MSV-163MS-373-385-ACA-EXE-DE-H2-203-R00.2.pdf | P1724: =LD_01[[#This Row],[PASTA]]&"/"&LD_01[[#This Row],[ARQUIVO]] -> MSV-163MS-373-385/10.DR/MSV-163MS-373-385-ACA-EXE-DE-H2-203-R00.2.pdf
A1725: MSV-163MS-373-385-ACA-EXE-DE-H2-204 | B1725: =VLOOKUP(LD_01[[#This Row],[DOCUMENTO]],_xlfn.SORTBY(ARQUIVOS_RECEBIDOS!$E$2:$F$5010,ARQUIVOS_RECEBIDOS!$F$2:$F$5010,-1),2,) -> R00.2 | C1725: 02 | D1725: PRINCIPAL | E1725: 373-385 | F1725: PISTA PRINCIPAL - PROJETO DE DRENAGEM E OAC - SEÇÕES TRANSVERSAIS DO CANAL | G1725: DRENAGEM | H1725: =_xlfn.XLOOKUP(LD_01[[#This Row],[DISCIPLINA]],'CLASSES DE PROJETOS'!$F$3:$F$37,'CLASSES DE PROJETOS'!$C$3:$C$37) -> DR | I1725: =_xlfn.TEXTJOIN("/",TRUE,"MSV-163MS-"&LD_01[[#This Row],[OBRA]],_xlfn.XLOOKUP(LD_01[[#This Row],[SIGLA]],'CLASSES DE PROJETOS'!$C$3:$C$37,'CLASSES DE PROJETOS'!$E$3:$E$37)) -> MSV-163MS-373-385/10.DR | J1725: {=_xlfn.TEXTJOIN(",",TRUE,_xlfn._xlws.FILTER(ARQUIVOS[ARQUIVO],(ARQUIVOS[DOCUMENTO]=LD_01[[#This Row],[DOCUMENTO]])*(ARQUIVOS[REVISÃO]=LD_01[[#This Row],[REVISÃO]])*(ARQUIVOS[EXTENSÃO]="pdf")))} -> MSV-163MS-373-385-ACA-EXE-DE-H2-204-R00.2.pdf | K1725: {=_xlfn.TEXTJOIN(", ",TRUE,_xlfn.UNIQUE(_xlfn._xlws.FILTER(ARQUIVOS_RECEBIDOS!$F$2:$F$5010,ARQUIVOS_RECEBIDOS!$E$2:$E$5010=LD_01[[#This Row],[DOCUMENTO]])))} -> R00.2 | L1725: {=_xlfn.TEXTJOIN(",",TRUE,_xlfn._xlws.FILTER(ARQUIVOS[EXTENSÃO],(ARQUIVOS[DOCUMENTO]=LD_01[[#This Row],[DOCUMENTO]])*(ARQUIVOS[REVISÃO]=LD_01[[#This Row],[REVISÃO]])))} -> dwg,pdf | M1725: {=_xlfn.UNIQUE(_xlfn._xlws.FILTER(ARQUIVOS[DATA RECEBIMENTO],(ARQUIVOS[DOCUMENTO]=LD_01[[#This Row],[DOCUMENTO]])*(ARQUIVOS[REVISÃO]=LD_01[[#This Row],[REVISÃO]])))} -> 46041 | N1725: ="https://aterpa.sharepoint.com//sites/A373_Projetos/Documentos Compartilhados/11.Sala Tecnica/01.PROJETOS/ANO "&TEXT(LD_01[[#This Row],[ANO]],"00") -> https://aterpa.sharepoint.com//sites/A373_Projetos/Documentos Compartilhados/11.Sala Tecnica/01.PROJETOS/ANO 02 | O1725: =_xlfn.TEXTJOIN("/",TRUE,LD_01[[#This Row],[RAIZ SHAREPOINT]],LD_01[[#This Row],[PASTA]],LD_01[[#This Row],[ARQUIVO]]) -> https://aterpa.sharepoint.com//sites/A373_Projetos/Documentos Compartilhados/11.Sala Tecnica/01.PROJETOS/ANO 02/MSV-163MS-373-385/10.DR/MSV-163MS-373-385-ACA-EXE-DE-H2-204-R00.2.pdf | P1725: =LD_01[[#This Row],[PASTA]]&"/"&LD_01[[#This Row],[ARQUIVO]] -> MSV-163MS-373-385/10.DR/MSV-163MS-373-385-ACA-EXE-DE-H2-204-R00.2.pdf
A1726: MSV-163MS-373-385-ACA-EXE-DE-H2-205 | B1726: =VLOOKUP(LD_01[[#This Row],[DOCUMENTO]],_xlfn.SORTBY(ARQUIVOS_RECEBIDOS!$E$2:$F$5010,ARQUIVOS_RECEBIDOS!$F$2:$F$5010,-1),2,) -> R00.2 | C1726: 02 | D1726: PRINCIPAL | E1726: 373-385 | F1726: PISTA PRINCIPAL - PROJETO DE DRENAGEM E OAC - SEÇÕES TRANSVERSAIS DO CANAL | G1726: DRENAGEM | H1726: =_xlfn.XLOOKUP(LD_01[[#This Row],[DISCIPLINA]],'CLASSES DE PROJETOS'!$F$3:$F$37,'CLASSES DE PROJETOS'!$C$3:$C$37) -> DR | I1726: =_xlfn.TEXTJOIN("/",TRUE,"MSV-163MS-"&LD_01[[#This Row],[OBRA]],_xlfn.XLOOKUP(LD_01[[#This Row],[SIGLA]],'CLASSES DE PROJETOS'!$C$3:$C$37,'CLASSES DE PROJETOS'!$E$3:$E$37)) -> MSV-163MS-373-385/10.DR | J1726: {=_xlfn.TEXTJOIN(",",TRUE,_xlfn._xlws.FILTER(ARQUIVOS[ARQUIVO],(ARQUIVOS[DOCUMENTO]=LD_01[[#This Row],[DOCUMENTO]])*(ARQUIVOS[REVISÃO]=LD_01[[#This Row],[REVISÃO]])*(ARQUIVOS[EXTENSÃO]="pdf")))} -> MSV-163MS-373-385-ACA-EXE-DE-H2-205-R00.2.pdf | K1726: {=_xlfn.TEXTJOIN(", ",TRUE,_xlfn.UNIQUE(_xlfn._xlws.FILTER(ARQUIVOS_RECEBIDOS!$F$2:$F$5010,ARQUIVOS_RECEBIDOS!$E$2:$E$5010=LD_01[[#This Row],[DOCUMENTO]])))} -> R00.2 | L1726: {=_xlfn.TEXTJOIN(",",TRUE,_xlfn._xlws.FILTER(ARQUIVOS[EXTENSÃO],(ARQUIVOS[DOCUMENTO]=LD_01[[#This Row],[DOCUMENTO]])*(ARQUIVOS[REVISÃO]=LD_01[[#This Row],[REVISÃO]])))} -> dwg,pdf | M1726: {=_xlfn.UNIQUE(_xlfn._xlws.FILTER(ARQUIVOS[DATA RECEBIMENTO],(ARQUIVOS[DOCUMENTO]=LD_01[[#This Row],[DOCUMENTO]])*(ARQUIVOS[REVISÃO]=LD_01[[#This Row],[REVISÃO]])))} -> 46041 | N1726: ="https://aterpa.sharepoint.com//sites/A373_Projetos/Documentos Compartilhados/11.Sala Tecnica/01.PROJETOS/ANO "&TEXT(LD_01[[#This Row],[ANO]],"00") -> https://aterpa.sharepoint.com//sites/A373_Projetos/Documentos Compartilhados/11.Sala Tecnica/01.PROJETOS/ANO 02 | O1726: =_xlfn.TEXTJOIN("/",TRUE,LD_01[[#This Row],[RAIZ SHAREPOINT]],LD_01[[#This Row],[PASTA]],LD_01[[#This Row],[ARQUIVO]]) -> https://aterpa.sharepoint.com//sites/A373_Projetos/Documentos Compartilhados/11.Sala Tecnica/01.PROJETOS/ANO 02/MSV-163MS-373-385/10.DR/MSV-163MS-373-385-ACA-EXE-DE-H2-205-R00.2.pdf | P1726: =LD_01[[#This Row],[PASTA]]&"/"&LD_01[[#This Row],[ARQUIVO]] -> MSV-163MS-373-385/10.DR/MSV-163MS-373-385-ACA-EXE-DE-H2-205-R00.2.pdf
A1727: MSV-163MS-373-385-ACA-EXE-DE-H2-206 | B1727: =VLOOKUP(LD_01[[#This Row],[DOCUMENTO]],_xlfn.SORTBY(ARQUIVOS_RECEBIDOS!$E$2:$F$5010,ARQUIVOS_RECEBIDOS!$F$2:$F$5010,-1),2,) -> R00.2 | C1727: 02 | D1727: PRINCIPAL | E1727: 373-385 | F1727: PISTA PRINCIPAL - PROJETO DE DRENAGEM E OAC - SEÇÕES TRANSVERSAIS DO CANAL | G1727: DRENAGEM | H1727: =_xlfn.XLOOKUP(LD_01[[#This Row],[DISCIPLINA]],'CLASSES DE PROJETOS'!$F$3:$F$37,'CLASSES DE PROJETOS'!$C$3:$C$37) -> DR | I1727: =_xlfn.TEXTJOIN("/",TRUE,"MSV-163MS-"&LD_01[[#This Row],[OBRA]],_xlfn.XLOOKUP(LD_01[[#This Row],[SIGLA]],'CLASSES DE PROJETOS'!$C$3:$C$37,'CLASSES DE PROJETOS'!$E$3:$E$37)) -> MSV-163MS-373-385/10.DR | J1727: {=_xlfn.TEXTJOIN(",",TRUE,_xlfn._xlws.FILTER(ARQUIVOS[ARQUIVO],(ARQUIVOS[DOCUMENTO]=LD_01[[#This Row],[DOCUMENTO]])*(ARQUIVOS[REVISÃO]=LD_01[[#This Row],[REVISÃO]])*(ARQUIVOS[EXTENSÃO]="pdf")))} -> MSV-163MS-373-385-ACA-EXE-DE-H2-206-R00.2.pdf | K1727: {=_xlfn.TEXTJOIN(", ",TRUE,_xlfn.UNIQUE(_xlfn._xlws.FILTER(ARQUIVOS_RECEBIDOS!$F$2:$F$5010,ARQUIVOS_RECEBIDOS!$E$2:$E$5010=LD_01[[#This Row],[DOCUMENTO]])))} -> R00.2 | L1727: {=_xlfn.TEXTJOIN(",",TRUE,_xlfn._xlws.FILTER(ARQUIVOS[EXTENSÃO],(ARQUIVOS[DOCUMENTO]=LD_01[[#This Row],[DOCUMENTO]])*(ARQUIVOS[REVISÃO]=LD_01[[#This Row],[REVISÃO]])))} -> dwg,pdf | M1727: {=_xlfn.UNIQUE(_xlfn._xlws.FILTER(ARQUIVOS[DATA RECEBIMENTO],(ARQUIVOS[DOCUMENTO]=LD_01[[#This Row],[DOCUMENTO]])*(ARQUIVOS[REVISÃO]=LD_01[[#This Row],[REVISÃO]])))} -> 46041 | N1727: ="https://aterpa.sharepoint.com//sites/A373_Projetos/Documentos Compartilhados/11.Sala Tecnica/01.PROJETOS/ANO "&TEXT(LD_01[[#This Row],[ANO]],"00") -> https://aterpa.sharepoint.com//sites/A373_Projetos/Documentos Compartilhados/11.Sala Tecnica/01.PROJETOS/ANO 02 | O1727: =_xlfn.TEXTJOIN("/",TRUE,LD_01[[#This Row],[RAIZ SHAREPOINT]],LD_01[[#This Row],[PASTA]],LD_01[[#This Row],[ARQUIVO]]) -> https://aterpa.sharepoint.com//sites/A373_Projetos/Documentos Compartilhados/11.Sala Tecnica/01.PROJETOS/ANO 02/MSV-163MS-373-385/10.DR/MSV-163MS-373-385-ACA-EXE-DE-H2-206-R00.2.pdf | P1727: =LD_01[[#This Row],[PASTA]]&"/"&LD_01[[#This Row],[ARQUIVO]] -> MSV-163MS-373-385/10.DR/MSV-163MS-373-385-ACA-EXE-DE-H2-206-R00.2.pdf
A1728: MSV-163MS-373-385-ACA-EXE-DE-I2-001 | B1728: =VLOOKUP(LD_01[[#This Row],[DOCUMENTO]],_xlfn.SORTBY(ARQUIVOS_RECEBIDOS!$E$2:$F$5010,ARQUIVOS_RECEBIDOS!$F$2:$F$5010,-1),2,) -> R00.3 | C1728: 02 | D1728: PRINCIPAL | E1728: 373-385 | F1728: PISTA PRINCIPAL - PROJETO DE PAVIMENTAÇÃO - PLANTA | G1728: PAVIMENTAÇÃO | H1728: =_xlfn.XLOOKUP(LD_01[[#This Row],[DISCIPLINA]],'CLASSES DE PROJETOS'!$F$3:$F$37,'CLASSES DE PROJETOS'!$C$3:$C$37) -> PV | I1728: =_xlfn.TEXTJOIN("/",TRUE,"MSV-163MS-"&LD_01[[#This Row],[OBRA]],_xlfn.XLOOKUP(LD_01[[#This Row],[SIGLA]],'CLASSES DE PROJETOS'!$C$3:$C$37,'CLASSES DE PROJETOS'!$E$3:$E$37)) -> MSV-163MS-373-385/28.PV | J1728: {=_xlfn.TEXTJOIN(",",TRUE,_xlfn._xlws.FILTER(ARQUIVOS[ARQUIVO],(ARQUIVOS[DOCUMENTO]=LD_01[[#This Row],[DOCUMENTO]])*(ARQUIVOS[REVISÃO]=LD_01[[#This Row],[REVISÃO]])*(ARQUIVOS[EXTENSÃO]="pdf")))} -> MSV-163MS-373-385-ACA-EXE-DE-I2-001-R00.3.pdf | K1728: {=_xlfn.TEXTJOIN(", ",TRUE,_xlfn.UNIQUE(_xlfn._xlws.FILTER(ARQUIVOS_RECEBIDOS!$F$2:$F$5010,ARQUIVOS_RECEBIDOS!$E$2:$E$5010=LD_01[[#This Row],[DOCUMENTO]])))} -> R00.3 | L1728: {=_xlfn.TEXTJOIN(",",TRUE,_xlfn._xlws.FILTER(ARQUIVOS[EXTENSÃO],(ARQUIVOS[DOCUMENTO]=LD_01[[#This Row],[DOCUMENTO]])*(ARQUIVOS[REVISÃO]=LD_01[[#This Row],[REVISÃO]])))} -> dwg,pdf | M1728: {=_xlfn.UNIQUE(_xlfn._xlws.FILTER(ARQUIVOS[DATA RECEBIMENTO],(ARQUIVOS[DOCUMENTO]=LD_01[[#This Row],[DOCUMENTO]])*(ARQUIVOS[REVISÃO]=LD_01[[#This Row],[REVISÃO]])))} -> 46041 | N1728: ="https://aterpa.sharepoint.com//sites/A373_Projetos/Documentos Compartilhados/11.Sala Tecnica/01.PROJETOS/ANO "&TEXT(LD_01[[#This Row],[ANO]],"00") -> https://aterpa.sharepoint.com//sites/A373_Projetos/Documentos Compartilhados/11.Sala Tecnica/01.PROJETOS/ANO 02 | O1728: =_xlfn.TEXTJOIN("/",TRUE,LD_01[[#This Row],[RAIZ SHAREPOINT]],LD_01[[#This Row],[PASTA]],LD_01[[#This Row],[ARQUIVO]]) -> https://aterpa.sharepoint.com//sites/A373_Projetos/Documentos Compartilhados/11.Sala Tecnica/01.PROJETOS/ANO 02/MSV-163MS-373-385/28.PV/MSV-163MS-373-385-ACA-EXE-DE-I2-001-R00.3.pdf | P1728: =LD_01[[#This Row],[PASTA]]&"/"&LD_01[[#This Row],[ARQUIVO]] -> MSV-163MS-373-385/28.PV/MSV-163MS-373-385-ACA-EXE-DE-I2-001-R00.3.pdf
A1729: MSV-163MS-373-385-ACA-EXE-DE-I2-002 | B1729: =VLOOKUP(LD_01[[#This Row],[DOCUMENTO]],_xlfn.SORTBY(ARQUIVOS_RECEBIDOS!$E$2:$F$5010,ARQUIVOS_RECEBIDOS!$F$2:$F$5010,-1),2,) -> R00.3 | C1729: 02 | D1729: PRINCIPAL | E1729: 373-385 | F1729: PISTA PRINCIPAL - PROJETO DE PAVIMENTAÇÃO - PLANTA | G1729: PAVIMENTAÇÃO | H1729: =_xlfn.XLOOKUP(LD_01[[#This Row],[DISCIPLINA]],'CLASSES DE PROJETOS'!$F$3:$F$37,'CLASSES DE PROJETOS'!$C$3:$C$37) -> PV | I1729: =_xlfn.TEXTJOIN("/",TRUE,"MSV-163MS-"&LD_01[[#This Row],[OBRA]],_xlfn.XLOOKUP(LD_01[[#This Row],[SIGLA]],'CLASSES DE PROJETOS'!$C$3:$C$37,'CLASSES DE PROJETOS'!$E$3:$E$37)) -> MSV-163MS-373-385/28.PV | J1729: {=_xlfn.TEXTJOIN(",",TRUE,_xlfn._xlws.FILTER(ARQUIVOS[ARQUIVO],(ARQUIVOS[DOCUMENTO]=LD_01[[#This Row],[DOCUMENTO]])*(ARQUIVOS[REVISÃO]=LD_01[[#This Row],[REVISÃO]])*(ARQUIVOS[EXTENSÃO]="pdf")))} -> MSV-163MS-373-385-ACA-EXE-DE-I2-002-R00.3.pdf | K1729: {=_xlfn.TEXTJOIN(", ",TRUE,_xlfn.UNIQUE(_xlfn._xlws.FILTER(ARQUIVOS_RECEBIDOS!$F$2:$F$5010,ARQUIVOS_RECEBIDOS!$E$2:$E$5010=LD_01[[#This Row],[DOCUMENTO]])))} -> R00.3 | L1729: {=_xlfn.TEXTJOIN(",",TRUE,_xlfn._xlws.FILTER(ARQUIVOS[EXTENSÃO],(ARQUIVOS[DOCUMENTO]=LD_01[[#This Row],[DOCUMENTO]])*(ARQUIVOS[REVISÃO]=LD_01[[#This Row],[REVISÃO]])))} -> dwg,pdf | M1729: {=_xlfn.UNIQUE(_xlfn._xlws.FILTER(ARQUIVOS[DATA RECEBIMENTO],(ARQUIVOS[DOCUMENTO]=LD_01[[#This Row],[DOCUMENTO]])*(ARQUIVOS[REVISÃO]=LD_01[[#This Row],[REVISÃO]])))} -> 46041 | N1729: ="https://aterpa.sharepoint.com//sites/A373_Projetos/Documentos Compartilhados/11.Sala Tecnica/01.PROJETOS/ANO "&TEXT(LD_01[[#This Row],[ANO]],"00") -> https://aterpa.sharepoint.com//sites/A373_Projetos/Documentos Compartilhados/11.Sala Tecnica/01.PROJETOS/ANO 02 | O1729: =_xlfn.TEXTJOIN("/",TRUE,LD_01[[#This Row],[RAIZ SHAREPOINT]],LD_01[[#This Row],[PASTA]],LD_01[[#This Row],[ARQUIVO]]) -> https://aterpa.sharepoint.com//sites/A373_Projetos/Documentos Compartilhados/11.Sala Tecnica/01.PROJETOS/ANO 02/MSV-163MS-373-385/28.PV/MSV-163MS-373-385-ACA-EXE-DE-I2-002-R00.3.pdf | P1729: =LD_01[[#This Row],[PASTA]]&"/"&LD_01[[#This Row],[ARQUIVO]] -> MSV-163MS-373-385/28.PV/MSV-163MS-373-385-ACA-EXE-DE-I2-002-R00.3.pdf
A1730: MSV-163MS-373-385-ACA-EXE-DE-I2-003 | B1730: =VLOOKUP(LD_01[[#This Row],[DOCUMENTO]],_xlfn.SORTBY(ARQUIVOS_RECEBIDOS!$E$2:$F$5010,ARQUIVOS_RECEBIDOS!$F$2:$F$5010,-1),2,) -> R00.3 | C1730: 02 | D1730: PRINCIPAL | E1730: 373-385 | F1730: PISTA PRINCIPAL - PROJETO DE PAVIMENTAÇÃO - PLANTA | G1730: PAVIMENTAÇÃO | H1730: =_xlfn.XLOOKUP(LD_01[[#This Row],[DISCIPLINA]],'CLASSES DE PROJETOS'!$F$3:$F$37,'CLASSES DE PROJETOS'!$C$3:$C$37) -> PV | I1730: =_xlfn.TEXTJOIN("/",TRUE,"MSV-163MS-"&LD_01[[#This Row],[OBRA]],_xlfn.XLOOKUP(LD_01[[#This Row],[SIGLA]],'CLASSES DE PROJETOS'!$C$3:$C$37,'CLASSES DE PROJETOS'!$E$3:$E$37)) -> MSV-163MS-373-385/28.PV | J1730: {=_xlfn.TEXTJOIN(",",TRUE,_xlfn._xlws.FILTER(ARQUIVOS[ARQUIVO],(ARQUIVOS[DOCUMENTO]=LD_01[[#This Row],[DOCUMENTO]])*(ARQUIVOS[REVISÃO]=LD_01[[#This Row],[REVISÃO]])*(ARQUIVOS[EXTENSÃO]="pdf")))} -> MSV-163MS-373-385-ACA-EXE-DE-I2-003-R00.3.pdf | K1730: {=_xlfn.TEXTJOIN(", ",TRUE,_xlfn.UNIQUE(_xlfn._xlws.FILTER(ARQUIVOS_RECEBIDOS!$F$2:$F$5010,ARQUIVOS_RECEBIDOS!$E$2:$E$5010=LD_01[[#This Row],[DOCUMENTO]])))} -> R00.3 | L1730: {=_xlfn.TEXTJOIN(",",TRUE,_xlfn._xlws.FILTER(ARQUIVOS[EXTENSÃO],(ARQUIVOS[DOCUMENTO]=LD_01[[#This Row],[DOCUMENTO]])*(ARQUIVOS[REVISÃO]=LD_01[[#This Row],[REVISÃO]])))} -> dwg,pdf | M1730: {=_xlfn.UNIQUE(_xlfn._xlws.FILTER(ARQUIVOS[DATA RECEBIMENTO],(ARQUIVOS[DOCUMENTO]=LD_01[[#This Row],[DOCUMENTO]])*(ARQUIVOS[REVISÃO]=LD_01[[#This Row],[REVISÃO]])))} -> 46041 | N1730: ="https://aterpa.sharepoint.com//sites/A373_Projetos/Documentos Compartilhados/11.Sala Tecnica/01.PROJETOS/ANO "&TEXT(LD_01[[#This Row],[ANO]],"00") -> https://aterpa.sharepoint.com//sites/A373_Projetos/Documentos Compartilhados/11.Sala Tecnica/01.PROJETOS/ANO 02 | O1730: =_xlfn.TEXTJOIN("/",TRUE,LD_01[[#This Row],[RAIZ SHAREPOINT]],LD_01[[#This Row],[PASTA]],LD_01[[#This Row],[ARQUIVO]]) -> https://aterpa.sharepoint.com//sites/A373_Projetos/Documentos Compartilhados/11.Sala Tecnica/01.PROJETOS/ANO 02/MSV-163MS-373-385/28.PV/MSV-163MS-373-385-ACA-EXE-DE-I2-003-R00.3.pdf | P1730: =LD_01[[#This Row],[PASTA]]&"/"&LD_01[[#This Row],[ARQUIVO]] -> MSV-163MS-373-385/28.PV/MSV-163MS-373-385-ACA-EXE-DE-I2-003-R00.3.pdf
A1731: MSV-163MS-373-385-ACA-EXE-DE-I2-004 | B1731: =VLOOKUP(LD_01[[#This Row],[DOCUMENTO]],_xlfn.SORTBY(ARQUIVOS_RECEBIDOS!$E$2:$F$5010,ARQUIVOS_RECEBIDOS!$F$2:$F$5010,-1),2,) -> R00.3 | C1731: 02 | D1731: PRINCIPAL | E1731: 373-385 | F1731: PISTA PRINCIPAL - PROJETO DE PAVIMENTAÇÃO - PLANTA | G1731: PAVIMENTAÇÃO | H1731: =_xlfn.XLOOKUP(LD_01[[#This Row],[DISCIPLINA]],'CLASSES DE PROJETOS'!$F$3:$F$37,'CLASSES DE PROJETOS'!$C$3:$C$37) -> PV | I1731: =_xlfn.TEXTJOIN("/",TRUE,"MSV-163MS-"&LD_01[[#This Row],[OBRA]],_xlfn.XLOOKUP(LD_01[[#This Row],[SIGLA]],'CLASSES DE PROJETOS'!$C$3:$C$37,'CLASSES DE PROJETOS'!$E$3:$E$37)) -> MSV-163MS-373-385/28.PV | J1731: {=_xlfn.TEXTJOIN(",",TRUE,_xlfn._xlws.FILTER(ARQUIVOS[ARQUIVO],(ARQUIVOS[DOCUMENTO]=LD_01[[#This Row],[DOCUMENTO]])*(ARQUIVOS[REVISÃO]=LD_01[[#This Row],[REVISÃO]])*(ARQUIVOS[EXTENSÃO]="pdf")))} -> MSV-163MS-373-385-ACA-EXE-DE-I2-004-R00.3.pdf | K1731: {=_xlfn.TEXTJOIN(", ",TRUE,_xlfn.UNIQUE(_xlfn._xlws.FILTER(ARQUIVOS_RECEBIDOS!$F$2:$F$5010,ARQUIVOS_RECEBIDOS!$E$2:$E$5010=LD_01[[#This Row],[DOCUMENTO]])))} -> R00.3 | L1731: {=_xlfn.TEXTJOIN(",",TRUE,_xlfn._xlws.FILTER(ARQUIVOS[EXTENSÃO],(ARQUIVOS[DOCUMENTO]=LD_01[[#This Row],[DOCUMENTO]])*(ARQUIVOS[REVISÃO]=LD_01[[#This Row],[REVISÃO]])))} -> dwg,pdf | M1731: {=_xlfn.UNIQUE(_xlfn._xlws.FILTER(ARQUIVOS[DATA RECEBIMENTO],(ARQUIVOS[DOCUMENTO]=LD_01[[#This Row],[DOCUMENTO]])*(ARQUIVOS[REVISÃO]=LD_01[[#This Row],[REVISÃO]])))} -> 46041 | N1731: ="https://aterpa.sharepoint.com//sites/A373_Projetos/Documentos Compartilhados/11.Sala Tecnica/01.PROJETOS/ANO "&TEXT(LD_01[[#This Row],[ANO]],"00") -> https://aterpa.sharepoint.com//sites/A373_Projetos/Documentos Compartilhados/11.Sala Tecnica/01.PROJETOS/ANO 02 | O1731: =_xlfn.TEXTJOIN("/",TRUE,LD_01[[#This Row],[RAIZ SHAREPOINT]],LD_01[[#This Row],[PASTA]],LD_01[[#This Row],[ARQUIVO]]) -> https://aterpa.sharepoint.com//sites/A373_Projetos/Documentos Compartilhados/11.Sala Tecnica/01.PROJETOS/ANO 02/MSV-163MS-373-385/28.PV/MSV-163MS-373-385-ACA-EXE-DE-I2-004-R00.3.pdf | P1731: =LD_01[[#This Row],[PASTA]]&"/"&LD_01[[#This Row],[ARQUIVO]] -> MSV-163MS-373-385/28.PV/MSV-163MS-373-385-ACA-EXE-DE-I2-004-R00.3.pdf
A1732: MSV-163MS-373-385-ACA-EXE-DE-I2-005 | B1732: =VLOOKUP(LD_01[[#This Row],[DOCUMENTO]],_xlfn.SORTBY(ARQUIVOS_RECEBIDOS!$E$2:$F$5010,ARQUIVOS_RECEBIDOS!$F$2:$F$5010,-1),2,) -> R00.3 | C1732: 02 | D1732: PRINCIPAL | E1732: 373-385 | F1732: PISTA PRINCIPAL - PROJETO DE PAVIMENTAÇÃO - PLANTA | G1732: PAVIMENTAÇÃO | H1732: =_xlfn.XLOOKUP(LD_01[[#This Row],[DISCIPLINA]],'CLASSES DE PROJETOS'!$F$3:$F$37,'CLASSES DE PROJETOS'!$C$3:$C$37) -> PV | I1732: =_xlfn.TEXTJOIN("/",TRUE,"MSV-163MS-"&LD_01[[#This Row],[OBRA]],_xlfn.XLOOKUP(LD_01[[#This Row],[SIGLA]],'CLASSES DE PROJETOS'!$C$3:$C$37,'CLASSES DE PROJETOS'!$E$3:$E$37)) -> MSV-163MS-373-385/28.PV | J1732: {=_xlfn.TEXTJOIN(",",TRUE,_xlfn._xlws.FILTER(ARQUIVOS[ARQUIVO],(ARQUIVOS[DOCUMENTO]=LD_01[[#This Row],[DOCUMENTO]])*(ARQUIVOS[REVISÃO]=LD_01[[#This Row],[REVISÃO]])*(ARQUIVOS[EXTENSÃO]="pdf")))} -> MSV-163MS-373-385-ACA-EXE-DE-I2-005-R00.3.pdf | K1732: {=_xlfn.TEXTJOIN(", ",TRUE,_xlfn.UNIQUE(_xlfn._xlws.FILTER(ARQUIVOS_RECEBIDOS!$F$2:$F$5010,ARQUIVOS_RECEBIDOS!$E$2:$E$5010=LD_01[[#This Row],[DOCUMENTO]])))} -> R00.3 | L1732: {=_xlfn.TEXTJOIN(",",TRUE,_xlfn._xlws.FILTER(ARQUIVOS[EXTENSÃO],(ARQUIVOS[DOCUMENTO]=LD_01[[#This Row],[DOCUMENTO]])*(ARQUIVOS[REVISÃO]=LD_01[[#This Row],[REVISÃO]])))} -> dwg,pdf | M1732: {=_xlfn.UNIQUE(_xlfn._xlws.FILTER(ARQUIVOS[DATA RECEBIMENTO],(ARQUIVOS[DOCUMENTO]=LD_01[[#This Row],[DOCUMENTO]])*(ARQUIVOS[REVISÃO]=LD_01[[#This Row],[REVISÃO]])))} -> 46041 | N1732: ="https://aterpa.sharepoint.com//sites/A373_Projetos/Documentos Compartilhados/11.Sala Tecnica/01.PROJETOS/ANO "&TEXT(LD_01[[#This Row],[ANO]],"00") -> https://aterpa.sharepoint.com//sites/A373_Projetos/Documentos Compartilhados/11.Sala Tecnica/01.PROJETOS/ANO 02 | O1732: =_xlfn.TEXTJOIN("/",TRUE,LD_01[[#This Row],[RAIZ SHAREPOINT]],LD_01[[#This Row],[PASTA]],LD_01[[#This Row],[ARQUIVO]]) -> https://aterpa.sharepoint.com//sites/A373_Projetos/Documentos Compartilhados/11.Sala Tecnica/01.PROJETOS/ANO 02/MSV-163MS-373-385/28.PV/MSV-163MS-373-385-ACA-EXE-DE-I2-005-R00.3.pdf | P1732: =LD_01[[#This Row],[PASTA]]&"/"&LD_01[[#This Row],[ARQUIVO]] -> MSV-163MS-373-385/28.PV/MSV-163MS-373-385-ACA-EXE-DE-I2-005-R00.3.pdf
A1733: MSV-163MS-373-385-ACA-EXE-DE-I2-006 | B1733: =VLOOKUP(LD_01[[#This Row],[DOCUMENTO]],_xlfn.SORTBY(ARQUIVOS_RECEBIDOS!$E$2:$F$5010,ARQUIVOS_RECEBIDOS!$F$2:$F$5010,-1),2,) -> R00.3 | C1733: 02 | D1733: PRINCIPAL | E1733: 373-385 | F1733: PISTA PRINCIPAL - PROJETO DE PAVIMENTAÇÃO - PLANTA | G1733: PAVIMENTAÇÃO | H1733: =_xlfn.XLOOKUP(LD_01[[#This Row],[DISCIPLINA]],'CLASSES DE PROJETOS'!$F$3:$F$37,'CLASSES DE PROJETOS'!$C$3:$C$37) -> PV | I1733: =_xlfn.TEXTJOIN("/",TRUE,"MSV-163MS-"&LD_01[[#This Row],[OBRA]],_xlfn.XLOOKUP(LD_01[[#This Row],[SIGLA]],'CLASSES DE PROJETOS'!$C$3:$C$37,'CLASSES DE PROJETOS'!$E$3:$E$37)) -> MSV-163MS-373-385/28.PV | J1733: {=_xlfn.TEXTJOIN(",",TRUE,_xlfn._xlws.FILTER(ARQUIVOS[ARQUIVO],(ARQUIVOS[DOCUMENTO]=LD_01[[#This Row],[DOCUMENTO]])*(ARQUIVOS[REVISÃO]=LD_01[[#This Row],[REVISÃO]])*(ARQUIVOS[EXTENSÃO]="pdf")))} -> MSV-163MS-373-385-ACA-EXE-DE-I2-006-R00.3.pdf | K1733: {=_xlfn.TEXTJOIN(", ",TRUE,_xlfn.UNIQUE(_xlfn._xlws.FILTER(ARQUIVOS_RECEBIDOS!$F$2:$F$5010,ARQUIVOS_RECEBIDOS!$E$2:$E$5010=LD_01[[#This Row],[DOCUMENTO]])))} -> R00.3 | L1733: {=_xlfn.TEXTJOIN(",",TRUE,_xlfn._xlws.FILTER(ARQUIVOS[EXTENSÃO],(ARQUIVOS[DOCUMENTO]=LD_01[[#This Row],[DOCUMENTO]])*(ARQUIVOS[REVISÃO]=LD_01[[#This Row],[REVISÃO]])))} -> dwg,pdf | M1733: {=_xlfn.UNIQUE(_xlfn._xlws.FILTER(ARQUIVOS[DATA RECEBIMENTO],(ARQUIVOS[DOCUMENTO]=LD_01[[#This Row],[DOCUMENTO]])*(ARQUIVOS[REVISÃO]=LD_01[[#This Row],[REVISÃO]])))} -> 46041 | N1733: ="https://aterpa.sharepoint.com//sites/A373_Projetos/Documentos Compartilhados/11.Sala Tecnica/01.PROJETOS/ANO "&TEXT(LD_01[[#This Row],[ANO]],"00") -> https://aterpa.sharepoint.com//sites/A373_Projetos/Documentos Compartilhados/11.Sala Tecnica/01.PROJETOS/ANO 02 | O1733: =_xlfn.TEXTJOIN("/",TRUE,LD_01[[#This Row],[RAIZ SHAREPOINT]],LD_01[[#This Row],[PASTA]],LD_01[[#This Row],[ARQUIVO]]) -> https://aterpa.sharepoint.com//sites/A373_Projetos/Documentos Compartilhados/11.Sala Tecnica/01.PROJETOS/ANO 02/MSV-163MS-373-385/28.PV/MSV-163MS-373-385-ACA-EXE-DE-I2-006-R00.3.pdf | P1733: =LD_01[[#This Row],[PASTA]]&"/"&LD_01[[#This Row],[ARQUIVO]] -> MSV-163MS-373-385/28.PV/MSV-163MS-373-385-ACA-EXE-DE-I2-006-R00.3.pdf
... A1903: MSV-163MS-373-385-ACA-EXE-RT-Q1-001 | B1903: =VLOOKUP(LD_01[[#This Row],[DOCUMENTO]],_xlfn.SORTBY(ARQUIVOS_RECEBIDOS!$E$2:$F$5010,ARQUIVOS_RECEBIDOS!$F$2:$F$5010,-1),2,) -> R00.3 | C1903: 02 | D1903: PRINCIPAL | E1903: 373-385 | F1903: PISTA PRINCIPAL - PROJETO DE DESAPROPRIAÇÃO - RELATÓRIO DO PROJETO DE DESAPROPRIAÇÃO | G1903: DESAPROPRIAÇÃO | H1903: =_xlfn.XLOOKUP(LD_01[[#This Row],[DISCIPLINA]],'CLASSES DE PROJETOS'!$F$3:$F$37,'CLASSES DE PROJETOS'!$C$3:$C$37) -> DS | I1903: =_xlfn.TEXTJOIN("/",TRUE,"MSV-163MS-"&LD_01[[#This Row],[OBRA]],_xlfn.XLOOKUP(LD_01[[#This Row],[SIGLA]],'CLASSES DE PROJETOS'!$C$3:$C$37,'CLASSES DE PROJETOS'!$E$3:$E$37)) -> MSV-163MS-373-385/11.DS | J1903: {=_xlfn.TEXTJOIN(",",TRUE,_xlfn._xlws.FILTER(ARQUIVOS[ARQUIVO],(ARQUIVOS[DOCUMENTO]=LD_01[[#This Row],[DOCUMENTO]])*(ARQUIVOS[REVISÃO]=LD_01[[#This Row],[REVISÃO]])*(ARQUIVOS[EXTENSÃO]="pdf")))} -> MSV-163MS-373-385-ACA-EXE-RT-Q1-001-R00.3.pdf | K1903: {=_xlfn.TEXTJOIN(", ",TRUE,_xlfn.UNIQUE(_xlfn._xlws.FILTER(ARQUIVOS_RECEBIDOS!$F$2:$F$5010,ARQUIVOS_RECEBIDOS!$E$2:$E$5010=LD_01[[#This Row],[DOCUMENTO]])))} -> R00.3 | L1903: {=_xlfn.TEXTJOIN(",",TRUE,_xlfn._xlws.FILTER(ARQUIVOS[EXTENSÃO],(ARQUIVOS[DOCUMENTO]=LD_01[[#This Row],[DOCUMENTO]])*(ARQUIVOS[REVISÃO]=LD_01[[#This Row],[REVISÃO]])))} -> docx,pdf | M1903: {=_xlfn.UNIQUE(_xlfn._xlws.FILTER(ARQUIVOS[DATA RECEBIMENTO],(ARQUIVOS[DOCUMENTO]=LD_01[[#This Row],[DOCUMENTO]])*(ARQUIVOS[REVISÃO]=LD_01[[#This Row],[REVISÃO]])))} -> 46041 | N1903: ="https://aterpa.sharepoint.com//sites/A373_Projetos/Documentos Compartilhados/11.Sala Tecnica/01.PROJETOS/ANO "&TEXT(LD_01[[#This Row],[ANO]],"00") -> https://aterpa.sharepoint.com//sites/A373_Projetos/Documentos Compartilhados/11.Sala Tecnica/01.PROJETOS/ANO 02 | O1903: =_xlfn.TEXTJOIN("/",TRUE,LD_01[[#This Row],[RAIZ SHAREPOINT]],LD_01[[#This Row],[PASTA]],LD_01[[#This Row],[ARQUIVO]]) -> https://aterpa.sharepoint.com//sites/A373_Projetos/Documentos Compartilhados/11.Sala Tecnica/01.PROJETOS/ANO 02/MSV-163MS-373-385/11.DS/MSV-163MS-373-385-ACA-EXE-RT-Q1-001-R00.3.pdf | P1903: =LD_01[[#This Row],[PASTA]]&"/"&LD_01[[#This Row],[ARQUIVO]] -> MSV-163MS-373-385/11.DS/MSV-163MS-373-385-ACA-EXE-RT-Q1-001-R00.3.pdf
